Workbook

Sheet 2025 KES_전시 공통
B1: 증빙 상세 내역(공통_2025 KES 한국전자전)
B3: 구분 | C3: 항목 | D3: 소항목 | E3: 세부내역 | G3: 인원 | H3: 수량 | I3: 투입률 | J3: 금액 | K3: 비고 | L3: 사진 | M3: 공시된 엔지니어링 업체 노임 단가 기준표
B4: 공간디자인 | C4: 디자인 개발 | D4: ○기획 설계 -공간 기획 및 레이아웃 -투시도 작업 및 수정 보완 -사인 그래픽 2D 작업, 수정 보완 -마감 스펙 제안 | E4: 참여인력 | F4: ='(전시 증빙) 인건비 공통'!D5 -> 고급 기술자 | G4: ='(전시 증빙) 인건비 공통'!F5 -> 2 | H4: ='(전시 증빙) 인건비 공통'!G5 -> 16 | I4: ='(전시 증빙) 인건비 공통'!H5 -> 0.8 | J4: ='(전시 증빙) 인건비 공통'!I5 -> 13715057 | K4: ○기간: 2025.09.05 ~ 2025.09.26 (16일) * 25년 엔지니어링 건설 기술자 노임 단가 기준 (직접인건비, 직접경비, 제경비, 기술료 포함) [공간디자인 및 실시설계] 직접경비: 직접인건비의 10% 제경비: 직접인건비의 20% 기술료: (직접인건비+제경비)의 40%
F5: ='(전시 증빙) 인건비 공통'!D6 -> 중급 기술자 | G5: ='(전시 증빙) 인건비 공통'!F6 -> 1 | H5: ='(전시 증빙) 인건비 공통'!G6 -> 16 | I5: ='(전시 증빙) 인건비 공통'!H6 -> 0.8 | J5: ='(전시 증빙) 인건비 공통'!I6 -> 6471704.1
C6: 디자인 개발 소계 | J6: =SUM(J4:J5) -> 20186761
C7: 디자인 개발 합계 | J7: =TRUNC(J6,-6) -> 20000000
C8: 실시 설계 | D8: ○실시 설계 - 주최국 협의 업무 - 제작 및 도면설계 총괄 - 실시설계도 및 제작물 시공 감리 | E8: 참여인력 | F8: ='(전시 증빙) 인건비 공통'!D9 -> 고급 기술자 | G8: ='(전시 증빙) 인건비 공통'!F9 -> 1 | H8: ='(전시 증빙) 인건비 공통'!G9 -> 11 | I8: ='(전시 증빙) 인건비 공통'!H9 -> 1.2 | J8: ='(전시 증빙) 인건비 공통'!I9 -> 7071826.1 | K8: ○기간: 2025.09.29 ~ 2025.10.20 (11일) * 25년 엔지니어링 건설 기술자 노임 단가 기준 (직접인건비, 직접경비, 제경비, 기술료 포함) [공간디자인 및 실시설계] 직접경비: 직접인건비의 10% 제경비: 직접인건비의 20% 기술료: (직접인건비+제경비)의 40%
F9: ='(전시 증빙) 인건비 공통'!D10 -> 중급 기술자 | G9: ='(전시 증빙) 인건비 공통'!F10 -> 2 | H9: ='(전시 증빙) 인건비 공통'!G10 -> 11 | I9: ='(전시 증빙) 인건비 공통'!H10 -> 1.2 | J9: ='(전시 증빙) 인건비 공통'!I10 -> 13347890
C10: 실시 설계 소계 | J10: =SUM(J8:J9) -> 20419716
C11: 실시 설계 합계 | J11: =TRUNC(J10,-6) -> 20000000
B12: 2025 KES 한국전자전 소계 | J12: =SUM(J7,J11) -> 40000000
B13: 대행수수료 | J13: =J12*17.65% -> 7060000
B14: 2025 KES 한국전자전 총계 | J14: =SUM(J12:J13) -> 47060000

Sheet (전시 증빙) 인건비 공통
B2: 기획 및 디자인 인건비 금액 기준표
J3: *25년 엔지니어링 기술자 및 SW 기술자 노임 단가 기준
B4: 구분 | C4: 항목 | D4: 세부내역 | E4: 투입률 100% 기준 합계 | F4: 인원 | G4: 수량 | H4: 투입률 | I4: 비용 | J4: 비고 | L4: 구분 | M4: 직접인건비 | N4: 직접경비 | O4: 제경비 | P4: 기술료 | Q4: 최종 방향 금액 | R4: ** <참고자료> 「엔지니어링산업 진흥법」 제31조제2항에 따른 엔지니어링사업의 대가의 기준 "실비정액가산방식"
B5: 디자인 개발 | C5: KES 한국전자전 | D5: 고급 기술자 | E5: =VLOOKUP(D5,$L$4:$Q$8,6,FALSE) -> 535744.4 | F5: 2 | G5: 16 | H5: 0.8 | I5: =E5*G5*H5*F5 -> 13715057 | J5: 2025.09.05 ~ 2025.09.26 | L5: 특급 기술자 | M5: 358273 | N5: =M5*0.1 -> 35827.3 | O5: =M5*0.2 -> 71654.6 | P5: =(M5+O5)*0.4 -> 171971.04 | Q5: =SUM(M5:P5) -> 637725.94 | R5: 직접인건비
D6: 중급 기술자 | E6: =VLOOKUP(D6,$L$4:$Q$8,6,FALSE) -> 505601.88 | F6: 1 | G6: 16 | H6: 0.8 | I6: =E6*G6*H6*F6 -> 6471704.1 | L6: 고급 기술자 | M6: 300980 | N6: =M6*0.1 -> 30098 | O6: =M6*0.2 -> 60196 | P6: =(M6+O6)*0.4 -> 144470.4 | Q6: =SUM(M6:P6) -> 535744.4 | R6: 직접경비: 직접인건비의 10%
C7: 소계 | I7: =TRUNC(SUM(I5:I6),-6) -> 20000000 | L7: 중급 기술자 | M7: 284046 | N7: =M7*0.1 -> 28404.6 | O7: =M7*0.2 -> 56809.2 | P7: =(M7+O7)*0.4 -> 136342.08 | Q7: =SUM(M7:P7) -> 505601.88 | R7: 제경비: 직접인건비의 20%
B8: 디자인 개발비 합계 | I8: =SUM(I7) -> 20000000 | L8: 초급 기술자 | M8: 223644 | N8: =M8*0.1 -> 22364.4 | O8: =M8*0.2 -> 44728.8 | P8: =(M8+O8)*0.4 -> 107349.12 | Q8: =SUM(M8:P8) -> 398086.32 | R8: 기술료: (직접인건비+제경비)의 40%
B9: 실시 설계 | C9: KES 한국전자전 | D9: 고급 기술자 | E9: =VLOOKUP(D9,$L$4:$Q$8,6,FALSE) -> 535744.4 | F9: 1 | G9: 11 | H9: 1.2 | I9: =E9*F9*G9*H9 -> 7071826.1 | J9: 2025.09.29 ~ 2025.10.20
D10: 중급 기술자 | E10: =VLOOKUP(D10,$L$4:$Q$8,6,FALSE) -> 505601.88 | F10: 2 | G10: 11 | H10: 1.2 | I10: =E10*F10*G10*H10 -> 13347890 | L10: 투입률 (근로 100% = 1일 8시간) | N10: ** <참고자료> 「근로기준법」 제56조(연장ㆍ야간 및 휴일 근로)에 따른 투입률 기준 산정 방식, 해당 기준 이내 근로 투입
C11: 소계 | I11: =TRUNC(SUM(I9:I10),-6) -> 20000000 | L11: 0.8 | M11: =L11*8 -> 6.4 | N11: 1 | O11: 주간 근로 | P11: 1일 8시간
B12: 실시 설계비 합계 | I12: =SUM(I11) -> 20000000 | L12: 1 | M12: =L12*8 -> 8 | N12: 1.5 | O12: 연장 근로 | P12: 1일 8시간, 주 40시간(법정근로시간)을 초과하는 근로시간으로 소정근로시간을 초과한 근로 / 통상임금의 100분의 50 이상 가산
L13: 1.2 | M13: =L13*8 -> 9.6 | N13: 1.5 | O13: 야간 근로 | P13: 오후 10시 ~ 다음날 오전 6시 사이의 근로 / 통상임금의 100분의 50 이상 가산
N14: 1.75 | O14: 휴일 근로 | P14: 소정근로일이 아닌 휴일(공휴일 포함)에 일한 근로시간 / 8시간 이내의 휴일근로 : 통상임금의 100분의 50 이상 가산, 8시간 초과 휴일근로 : 통상임금의 100분의 100 가산

Sheet 2025 KES_전시 제작
B1: 증빙 상세 내역(전시제작_2025 KES 한국전자전)
B3: 구분 | C3: 항목 | D3: 소항목 | E3: 세부내역 | F3: 단위 | G3: 수량 | H3: 금액 | I3: 현장사진
B4: 1. 집기 제작 | C4: AI HOME(Living Room) | D4: 75" TV 벽장 | E4: [집기 제작] - 1,900X300X2,200 - 30X30 각재 및 12T, 15T 합판 NC 가공 - TV 브라켓 매립 타공 - 지정 펠트 마감 | F4: EA | G4: 1 | H4: 1600000
D5: 65" TV 벽장 | E5: [재활용] - 1,200X300X2,200 - 30X30 각재 및 12T, 15T 합판 NC 가공 - TV 브라켓 매립 타공 - 지정 필름 마감 재시공 | F5: EA | G5: 1 | H5: 200000
D6: 에어드레서 매립장 | E6: [재활용] - 900X700X2,200 - 30X30 각재 및 12T, 15T 합판 NC 가공 - 제품 변경으로 내경 사이즈 수정 - 지정 펠트 마감 재시공 | F6: EA | G6: 1 | H6: 800000
D7: 로봇 청소기 매립장 | E7: [재활용] - 600X400X750 - 30X30 각재 및 12T, 15T 합판 NC 가공 - 지정 펠트 마감 재시공 | F7: EA | G7: 1 | H7: 580000
D8: 제습기 매립장 | E8: [재활용] - 600X400X750 - 30X30 각재 및 12T, 15T 합판 NC 가공 - 지정 펠트 마감 재시공 | F8: EA | G8: 1 | H8: 580000
D9: 강아지 집 | E9: [집기 제작] - 800X400X1,000 - 30X30 각재 및 12T, 15T 합판 NC 가공 - 지정 펠트 마감 | F9: EA | G9: 1 | H9: 1130000
D10: 거실 테이블 | E10: [재활용] - 1,000X400X430 - 30X30 각재 및 12T, 15T 합판 NC 가공 - 지정 펠트 마감 재시공 - 1,200X600 상판 10T 강화유리 | F10: EA | G10: 1 | H10: 320000
D11: 거실 테이블 의자 | E11: [재활용] - 400X420X400 - 30X30 각재 및 12T, 15T 합판 NC 가공 - 지정 펠트 마감 재시공 | F11: EA | G11: 1 | H11: 180000
C12: AI HOME(Kitchen) | D12: 세탁기 매립장 | E12: [재활용] - 1,410X970X1,300 - 30X30 각재 및 12T, 15T 합판 NC 가공 - 지정 펠트 마감 | F12: EA | G12: 1 | H12: 0
D13: 옷걸이 장 | E13: [재활용] - 1,730X700X1,600 - 30X30 각재 및 12T, 15T 합판 NC 가공 - Ø20 SUS 파이프 w550 - 지정 펠트 마감 | F13: EA | G13: 1 | H13: 0
D14: 65" TV 벽장 | E14: [재활용] - 1,200X300X2,200 - 30X30 각재 및 12T, 15T 합판 NC 가공 - TV 브라켓 매립 타공 - 지정 필름 마감 재시공 | F14: EA | G14: 1 | H14: 200000
D15: 냉장고 매립장 | E15: [재활용] - 1,300X1,130X2,050 - 30X30 각재 및 12T, 15T 합판 NC 가공 - 지정 펠트 마감 | F15: EA | G15: 1 | H15: 0
D16: 정수기 멀티큐커 매립장 | E16: [재활용] - 1,420X780X2,050 - 30X30 각재 및 12T, 15T 합판 NC 가공 - 지정 펠트 마감 - 하부 도어 추가 | F16: EA | G16: 1 | H16: 100000
D17: 주방 테이블 | E17: [재활용] - 1,700X800X950 - 30X30 각재 및 12T, 15T 합판 NC 가공 - 하부 점검도어 - 지정 펠트 마감 - 상판 재도장 | F17: EA | G17: 1 | H17: 200000
C18: AI HOME(Bedroom) | D18: 65" TV 벽장 | E18: [재활용] - 1,200X300X2,200 - 30X30 각재 및 12T, 15T 합판 NC 가공 - TV 브라켓 매립 타공 - 지정 필름 마감 재시공 | F18: EA | G18: 1 | H18: 200000
D19: 에어컨 벽장 | E19: [재활용] - 1,600X300X2,000 - 30X30 각재 및 12T, 15T 합판 NC 가공 - 지정 펠트 마감 재시공 | F19: EA | G19: 1 | H19: 740000
D20: 코너타입 선반장 | E20: [재활용] - 380X280X1,200 - 30X30 각재 및 12T, 15T 합판 NC 가공 - 지정 펠트 마감 - 마감 보수 | F20: EA | G20: 1 | H20: 360000
D21: 커튼 집기 | E21: [재활용] - 1,700X300X2,200 - 30X30 각재 및 12T, 15T 합판 NC 가공 - 지정 펠트 마감 - 마감 보수 및 집기 디테일 수정(조명) | F21: EA | G21: 1 | H21: 200000
D22: 침대 모형집기 | E22: [재활용] - 2,070X1,450X950 - 30X30 각재 및 12T, 15T 합판 NC 가공 - 지정 펠트 마감 - 방향 수정 및 펠트 마감 재시공 | F22: EA | G22: 1 | H22: 780000
D23: 테이블 | E23: [집기 제작] - 900X300X950 - 30X30 각재 및 12T, 15T 합판 NC 가공 - 하부 점검도어 - 지정 펠트 마감 | F23: EA | G23: 1 | H23: 1500000
D24: 침실 테이블 | E24: [집기 제작] - 400X500X400 - 30X30 각재 및 12T, 15T 합판 NC 가공 - 지정 펠트 마감 - 650X700 10T 투명 강화유리 | F24: EA | G24: 1 | H24: 1260000
D25: 침실 테이블 의자 | E25: [집기 제작] - 650X550X650 - 30X30 각재 및 12T, 15T 합판 NC 가공 - 지정 펠트 마감 - 다릿발 기성제품 | F25: EA | G25: 1 | H25: 1400000
C26: AI School | D26: 디오라마 테이블 | E26: [재활용] - 2,000X1,700X950 - 30X30 각재 및 12T, 15T MDF NC 가공 - 하부장 도어 경첩 - 지정 시멘트 도장+지정색 우레탄 도장 마감 | F26: EA | G26: 1 | H26: 0
D27: AI Multi-tasking 테이블 | E27: [재활용] - 1.200X200X950 - 2T 갈바 절곡 및 용접 - 15X15 각파이프 내부보강 - 하부 점검도어 - 지정 시멘트 도장+지정색 우레탄 도장 마감 | F27: EA | G27: 1 | H27: 0
D28: 곡선형 핸즈온 테이블-A | E28: [집기 제작] - 2,650X1,200X750 - 30X30 각재 및 12T, 15T MDF NC 가공 - 하부 점검도어 - 지정색도장 마감 | F28: EA | G28: 1 | H28: 3200000
D29: 곡선형 핸즈온 테이블-B | E29: [집기 제작] - 1,935X720X750 - 30X30 각재 및 12T, 15T MDF NC 가공 - 하부 점검도어 - 지정색도장 마감 | F29: EA | G29: 1 | H29: 2600000
D30: 스툴 | E30: [재활용] - Ø470X420 - 30X30 각재 및 12T, 15T MDF NC 가공 - 지정 패브릭 마감 | F30: EA | G30: 10 | H30: 0
C31: AI Store | D31: 하부장 테이블 | E31: [집기 제작] - 1,550X600X900 - 30X30 각재 및 12T, 15T MDF NC 가공 - 하부장 도어 경첩 - 지정색도장 마감 | F31: EA | G31: 1 | H31: 1800000
D32: 원형 핸즈온 테이블 의자 | E32: [집기 제작] - 2,700X450X450 - 30X30 각재 및 12T, 15T MDF NC 가공 - 하부 덮게 탈착식 - Ø300X600 핸즈온 테이블 3EA - Ø30 파이프 절곡 및 용접 - 지정색도장 마감 | F32: SET | G32: 1 | H32: 2400000
C33: Energy Saving | D33: 벽장 집기 | E33: [재활용] - 1,400X500X2,690 - 30X30 각재 및 12T, 15T MDF NC 가공 - 1,400X500X250 상부 라이팅 박스 5T 아크릴 제작 설치 - 전면 제품 주변 라이팅 박스 제작 설치 - Bar LED 6000K 설치 - 지정색 도장 마감 변경 | F33: EA | G33: 5 | H33: 6500000
C34: 베뉴 전반 | D34: 제작집기 반입/설치 | E34: [제작집기 반입] - 3.5톤 2대 10월 1일 (평택창고->파주공장) - 1톤 1대 10월 1일 (평택창고->파주공장) - 3.5톤 4대 10월 18일 (파주공장->코엑스) - 1톤 3대 10월 18일 (파주공장->코엑스) - 집기 반입 | F34: 식 | G34: 1 | H34: 6050000
E35: [제작집기 셋팅비] - 집기 양중, 집기 배치, 집기 조립 등의 현장 작업 | F35: 식 | G35: 1 | H35: 10080000
C36: 집기 제작 소계 | H36: =SUM(H4:H35) -> 44960000
C37: 집기 제작 합계 | H37: =TRUNC(H36,-3) -> 44960000
B38: 2. 전시 제작 | C38: AI HOME(Living Room) | D38: 목공사 | E38: [Living Room 벽체] - 11,020X300X4,000 - 30X30각재, 9T,12T 합판 및 MDF NC 가공 - 상단 간접 박스 조성 - 제작 및 현장 설치 작업 | F38: M2 | G38: =11.02*4 -> 44.08 | H38: 10460000
E39: [Living Room 중간 벽체] - 4,000X200X2,800 - 3,900X200X2,800 - 30X30각재, 9T,12T 합판 및 MDF NC 가공 - 제작 및 현장 설치 작업 | F39: M2 | G39: =(4*2.8)+(3.9*2.8) -> 22.12
D40: 수장 공사 | E40: [Living Room 벽지 마감] - 11,020X4,000 - 퍼티 및 하지작업 - 지정 벽지 마감(필름 마감면적 제외) - 현장 설치 작업 | F40: M2 | G40: =(11.02*4)-22.12 -> 21.96 | H40: 4460000
E41: [Living Room 필름 마감] - 4,000X2,800, 3,900X2,800 - 퍼티 및 샌딩, 프라이머 - 지정 필름 마감 - 현장 설치 작업 | F41: M2 | G41: =(4*2.8)+(3.9*2.8) -> 22.12
...
