Workbook
Name _: #REF!
Name _: #REF!
Name ____________tt2: #REF!
Name __________tt2: #REF!
Name _________tt2: #REF!
Name ________SF1: #REF!
Name ________ST93: #REF!
Name _______123k: #REF!
Name _______SF1: #REF!
Name _______ST93: #REF!
Name _______tt2: #REF!
Name ______SP01: [1]!______SP01
Name ______SP01: [2]!______SP01
Name ______SP02: [1]!______SP02
Name ______SP02: [2]!______SP02
Name ______SP04: [1]!______SP04
Name ______SP04: [2]!______SP04
Name ______SP06: [1]!______SP06
Name ______SP06: [2]!______SP06
Name ______SP07: [1]!______SP07
Name ______SP07: [2]!______SP07
Name ______SP08: [1]!______SP08
Name ______SP08: [2]!______SP08
Name ______SP09: [1]!______SP09
Name ______SP09: [2]!______SP09
Name ______SP10: [1]!______SP10
Name ______SP10: [2]!______SP10
Name ______SP12: [1]!______SP12
Name ______SP12: [2]!______SP12
Name ______SP14: [1]!______SP14
Name ______SP14: [2]!______SP14
Name ______SP15: [1]!______SP15
Name ______SP15: [2]!______SP15
Name ______SP16: [1]!______SP16
Name ______SP16: [2]!______SP16
Name ______SP17: [1]!______SP17
Name ______SP17: [2]!______SP17
Name ______SP18: [1]!______SP18
Name ______SP18: [2]!______SP18
Name ______SP19: [1]!______SP19
Name ______SP19: [2]!______SP19
Name ______SP20: [1]!______SP20
Name ______SP20: [2]!______SP20
Name ______SP21: [1]!______SP21
Name ______SP21: [2]!______SP21
Name ______SP22: [1]!______SP22
Name ______SP22: [2]!______SP22
Name ______SP23: [1]!______SP23
Name ______SP23: [2]!______SP23
Name ______SP24: [1]!______SP24
Name ______SP24: [2]!______SP24
Name ______SP25: [1]!______SP25
Name ______SP25: [2]!______SP25
Name ______SP26: [1]!______SP26
Name ______SP26: [2]!______SP26
Name ______SP27: [1]!______SP27
Name ______SP27: [2]!______SP27
Name ______SP28: [1]!______SP28
Name ______SP28: [2]!______SP28
Name ______SP29: [1]!______SP29

Sheet 2026 WIS 예산
B1: 2026 WIS 거래명세서
B2: 공급받는자 | D2: [ 행사 표준 견적서 ] | G2: 공급자
B3: CLIENT | D3: 아래와 같이 견적 합니다. | G3: 회사명
B4: PROJECT | G4: 대표자
B5: PROJECT No. | G5: 사업자번호
B6: 견적금액 | C6: =G32 -> 896000000 | G6: 주소
B7: 담당자/연락처 | G7: 담당자/연락처
B11: 구분 | C11: 항목 | D11: 세부내역 | E11: 2025 거래가격 | F11: 2026 사전견적서 | G11: 2026 실행견적서 | H11: 비고
B12: 대관 | C12: 참가비 | D12: 독립부스 (96부스) | E12: 204950000 | F12: 204950000 | G12: 206800000 | H12: 2026 WIS (총 3일/시간외 사용)
C13: 대관료 합계 | E13: 204950000 | F13: =SUM(F12) -> 204950000 | G13: =G12 -> 206800000
B14: 전시 | C14: WIS 전시, 집기 제작 | D14: 기획비 | E14: 35000000 | F14: =[275]전시!G7 -> 35000000 | G14: ='1-1.전시_인건비'!J7+'1-1.전시_인건비'!J11 -> 29000000
D15: 전시, 집기공사 | E15: 485956000 | F15: =[275]전시!G10+[275]전시!G25 -> 374500000 | G15: ='2026 WIS_전시 제작(수정2)'!H120+'2026 WIS_전시 제작(수정2)'!H33 -> 355430000
D16: 필수보험료 | E16: 7530216 | F16: =[275]전시!G29 -> 5478533.5 | G16: ='2026 WIS_전시 제작(수정2)'!H124 -> 4559875.6
C17: WIS 전시, 집기 합계 | E17: 5.2848622e+08 | F17: =SUM(F14:F16) -> 4.1497853e+08 | G17: =SUM(G14:G16) -> 3.8898988e+08
B18: 키트 | C18: WIS 키트, 그래픽 | D18: 컨텐츠 및 디자인 | E18: 49763524 | F18: =[275]키트!D6 -> 4650000 | G18: ='2-1.키트_요약'!D9 -> 84080926
D19: 키트 | E19: 3563000 | F19: =[275]키트!D12 -> 82475000 | G19: ='2-1.키트_요약'!D8 -> 17559262 | H19: *VAC 및 스페이셜사이니지 제작, ACC월
D20: 설치 및 철거 | E20: 15997094 | F20: =[275]키트!D16 -> 17306810 | G20: ='2-1.키트_요약'!D10 -> 24541790
C21: WIS 키트, 그래픽 합계 | E21: 53326524 | F21: =SUM(F18:F20) -> 104431810 | G21: =SUM(G18:G20) -> 126181978
B22: 운영 | C22: 운영 | D22: 플래닝 | E22: 4000000 | F22: =[275]운영!I6 -> 5000000 | G22: ='3-1.운영'!I6 -> 5000000
D23: 인력 | E23: 57948500 | F23: =[275]운영!I18+[275]운영!I21 -> 41934300 | G23: ='3-1.운영'!I18+'3-1.운영'!I22 -> 43080200 | H23: 인건비 및 부대 인건비, 세탁비 포함
D24: 시스템 | E24: 7298222.5 | F24: =[275]운영!I27 -> 3260000 | G24: ='3-1.운영'!I28 -> 3222283 | H24: *전관방송 삭제 및 나우웨이팅 활용
D25: 제작물 | E25: 10306650 | F25: =[275]운영!I24+[275]운영!I31 -> 5559400 | G25: ='3-1.운영'!I25+'3-1.운영'!I32 -> 5216200 | H25: 국영문스크립트, 버즈 꾸미기 스티커 일체
D26: 보험 | E26: 1385964 | F26: =[275]운영!I44 -> 1747150 | G26: ='3-1.운영'!I45 -> 1282310 | H26: 행사 보험 및 근무자 보험 일체
D27: 렌탈, 네트워크, 운영물품 | E27: 14945000 | F27: =[275]운영!I33+[275]운영!I35+[275]운영!I37+[275]운영!I38+[275]운영!I39+[275]운영!I40 -> 15350000 | G27: ='3-1.운영'!I36+'3-1.운영'!I34+'3-1.운영'!I38+'3-1.운영'!I39+'3-1.운영'!I40+'3-1.운영'!I41 -> 15217750 | H27: 네트워크 및 무전기, 운영사무실 집기 등
D28: 물류 | E28: 495000 | F28: =[275]운영!I36 -> 500000 | G28: ='3-1.운영'!I37 -> 590000
C29: 운영 합계 | E29: 96379336 | F29: =SUM(F22:F28) -> 73350850 | G29: =SUM(G22:G28) -> 73608743
B30: 외주비 소계 | E30: 8.8314208e+08 | F30: =SUM(F13,F17,F21,F29) -> 7.9771119e+08 | G30: =SUM(G13,G17,G21,G29) -> 7.955806e+08
B31: 대행수수료 | E31: 1.1661984e+08 | F31: =SUM(F14:F15,F21:F25)*17.65%+SUM(F16,F26:F28)*5% -> 1.0170328e+08 | G31: =SUM(G14:G15,G21:G25)*17.65%+SUM(G16,G26:G28)*5% -> 1.0118106e+08
B32: 2025 WIS 총계 | E32: 999000000 | F32: =ROUNDDOWN(SUM(F30:F31),-5) -> 899400000 | G32: =ROUNDDOWN(SUM(G30:G31),-6) -> 896000000 | H32: 십만원 단위 이하 절사

Sheet 참관료

Sheet 1-1.전시_인건비
B1: 증빙 상세 내역(공통_2026 World IT Show)
K2: =J4/2 -> 5533735.2
B3: 구분 | C3: 항목 | D3: 소항목 | E3: 세부내역 | G3: 인원 | H3: 수량 | I3: 투입률 | J3: 금액 | K3: 비고 | L3: 사진 | M3: 공시된 엔지니어링 업체 노임 단가 기준표
B4: 공간디자인 | C4: 디자인 개발 | D4: ○기획 설계 -공간 기획 및 레이아웃 -투시도 작업 및 수정 보완 -사인 그래픽 2D 작업, 수정 보완 -마감 스펙 제안 | E4: 참여인력 | F4: ='1-2.전시_인건비 증빙'!D5 -> 고급 기술자 | G4: 1 | H4: ='1-2.전시_인건비 증빙'!G5 -> 20 | I4: ='1-2.전시_인건비 증빙'!H5 -> 0.5 | J4: ='1-2.전시_인건비 증빙'!I5 -> 11067470 | K4: ○기간: 2026.03.11 ~ 2026.04.07 (20일) * 26년 엔지니어링 건설 기술자 노임 단가 기준 (직접인건비, 직접경비, 제경비, 기술료 포함) [공간디자인 및 실시설계] 직접경비: 직접인건비의 10% 제경비: 직접인건비의 20% 기술료: (직접인건비+제경비)의 40%
F5: ='1-2.전시_인건비 증빙'!D6 -> 중급 기술자 | G5: ='1-2.전시_인건비 증빙'!F6 -> 1 | H5: ='1-2.전시_인건비 증빙'!G6 -> 20 | I5: ='1-2.전시_인건비 증빙'!H6 -> 0.8 | J5: ='1-2.전시_인건비 증빙'!I6 -> 8405530.2
C6: 디자인 개발 소계 | J6: =SUM(J4:J5) -> 19473001
C7: 디자인 개발 합계 | J7: =TRUNC(J6,-6) -> 19000000
C8: 실시 설계 | D8: ○실시 설계 - 제작 및 도면설계 총괄 - 실시설계도 및 제작물 시공 감리 | E8: 참여인력 | F8: ='1-2.전시_인건비 증빙'!D9 -> 고급 기술자 | G8: ='1-2.전시_인건비 증빙'!F9 -> 1 | H8: ='1-2.전시_인건비 증빙'!G9 -> 10 | I8: ='1-2.전시_인건비 증빙'!H9 -> 1 | J8: ='1-2.전시_인건비 증빙'!I9 -> 5533735.2 | K8: ○기간: 2026.04.08 ~ 2026.04.21 (10일) * 26년 엔지니어링 건설 기술자 노임 단가 기준 (직접인건비, 직접경비, 제경비, 기술료 포함) [공간디자인 및 실시설계] 직접경비: 직접인건비의 10% 제경비: 직접인건비의 20% 기술료: (직접인건비+제경비)의 40%
F9: ='1-2.전시_인건비 증빙'!D10 -> 중급 기술자 | G9: ='1-2.전시_인건비 증빙'!F10 -> 1 | H9: ='1-2.전시_인건비 증빙'!G10 -> 10 | I9: ='1-2.전시_인건비 증빙'!H10 -> 1 | J9: ='1-2.전시_인건비 증빙'!I10 -> 5253456.4
C10: 실시 설계 소계 | J10: =SUM(J8:J9) -> 10787192
C11: 실시 설계 합계 | J11: =TRUNC(J10,-6) -> 10000000
B12: 2026 World IT Show 소계 | J12: =SUM(J7,J11) -> 29000000
B13: 대행수수료 | J13: =J12*17.65% -> 5118500
B14: 2026 World IT Show 총계 | J14: =SUM(J12:J13) -> 34118500

Sheet 1-2.전시_인건비 증빙
B2: 기획 및 디자인 인건비 금액 기준표
J3: *26년 엔지니어링 기술자 및 SW 기술자 노임 단가 기준
B4: 구분 | C4: 항목 | D4: 세부내역 | E4: 투입률 100% 기준 합계 | F4: 인원 | G4: 수량 | H4: 투입률 | I4: 비용 | J4: 비고 | L4: 구분 | M4: 직접인건비 | N4: 직접경비 | O4: 제경비 | P4: 기술료 | Q4: 최종 방향 금액 | R4: ** <참고자료> 「엔지니어링산업 진흥법」 제31조제2항에 따른 엔지니어링사업의 대가의 기준 "실비정액가산방식"
B5: 디자인 개발 | C5: 2026 World IT Show | D5: 고급 기술자 | E5: =VLOOKUP(D5,$L$4:$Q$8,6,FALSE) -> 553373.52 | F5: 2 | G5: 20 | H5: 0.5 | I5: =E5*G5*H5*F5 -> 11067470 | J5: 2026.03.11 ~ 2026.04.07 | L5: 특급 기술자 | M5: 373353 | N5: =M5*0.1 -> 37335.3 | O5: =M5*0.2 -> 74670.6 | P5: =(M5+O5)*0.4 -> 179209.44 | Q5: =SUM(M5:P5) -> 664568.34 | R5: 직접인건비
D6: 중급 기술자 | E6: =VLOOKUP(D6,$L$4:$Q$8,6,FALSE) -> 525345.64 | F6: 1 | G6: 20 | H6: 0.8 | I6: =E6*G6*H6*F6 -> 8405530.2 | L6: 고급 기술자 | M6: 310884 | N6: =M6*0.1 -> 31088.4 | O6: =M6*0.2 -> 62176.8 | P6: =(M6+O6)*0.4 -> 149224.32 | Q6: =SUM(M6:P6) -> 553373.52 | R6: 직접경비: 직접인건비의 10%
C7: 소계 | I7: =TRUNC(SUM(I5:I6),-6) -> 19000000 | L7: 중급 기술자 | M7: 295138 | N7: =M7*0.1 -> 29513.8 | O7: =M7*0.2 -> 59027.6 | P7: =(M7+O7)*0.4 -> 141666.24 | Q7: =SUM(M7:P7) -> 525345.64 | R7: 제경비: 직접인건비의 20%
B8: 디자인 개발비 합계 | I8: =SUM(I7) -> 19000000 | L8: 초급 기술자 | M8: 235459 | N8: =M8*0.1 -> 23545.9 | O8: =M8*0.2 -> 47091.8 | P8: =(M8+O8)*0.4 -> 113020.32 | Q8: =SUM(M8:P8) -> 419117.02 | R8: 기술료: (직접인건비+제경비)의 40%
B9: 실시 설계 | C9: 2026 World IT Show | D9: 고급 기술자 | E9: =VLOOKUP(D9,$L$4:$Q$8,6,FALSE) -> 553373.52 | F9: 1 | G9: 10 | H9: 1 | I9: =E9*F9*G9*H9 -> 5533735.2 | J9: 2026.04.08 ~ 2026.04.21
D10: 중급 기술자 | E10: =VLOOKUP(D10,$L$4:$Q$8,6,FALSE) -> 525345.64 | F10: 1 | G10: 10 | H10: 1 | I10: =E10*F10*G10*H10 -> 5253456.4 | L10: 투입률 (근로 100% = 1일 8시간) | N10: ** <참고자료> 「근로기준법」 제56조(연장ㆍ야간 및 휴일 근로)에 따른 투입률 기준 산정 방식, 해당 기준 이내 근로 투입
C11: 소계 | I11: =TRUNC(SUM(I9:I10),-6) -> 10000000 | L11: 0.8 | M11: =L11*8 -> 6.4 | N11: 1 | O11: 주간 근로 | P11: 1일 8시간
B12: 실시 설계비 합계 | I12: =SUM(I11) -> 10000000 | L12: 1 | M12: =L12*8 -> 8 | N12: 1.5 | O12: 연장 근로 | P12: 1일 8시간, 주 40시간(법정근로시간)을 초과하는 근로시간으로 소정근로시간을 초과한 근로 / 통상임금의 100분의 50 이상 가산
L13: 1.2 | M13: =L13*8 -> 9.6 | N13: 1.5 | O13: 야간 근로 | P13: 오후 10시 ~ 다음날 오전 6시 사이의 근로 / 통상임금의 100분의 50 이상 가산
N14: 1.75 | O14: 휴일 근로 | P14: 소정근로일이 아닌 휴일(공휴일 포함)에 일한 근로시간 / 8시간 이내의 휴일근로 : 통상임금의 100분의 50 이상 가산, 8시간 초과 휴일근로 : 통상임금의 100분의 100 가산

Sheet 2026 WIS_전시 제작(수정2)
B1: 증빙 상세 내역(전시제작_2026 World IT Show)
B3: 구분 | C3: 항목 | D3: 소항목 | E3: 세부내역 | F3: 단위 | G3: 수량 | H3: 금액 | I3: 현장사진
B4: 1. 집기 제작 | C4: Intro | D4: 스페이셜 사이니지 거치대 | E4: [집기 제작] - 1,200X2,100X600 - 1.5T EGI 절곡 및 레이저 가공 - 각파이프 내부보강 - 잠금도어 경첩(자석) 하드웨어 - 지정 분체 도장 마감 | F4: EA | G4: 4 | H4: 11200000
D5: Micro RGB 바닥단 | E5: [집기 제작] - 4,500X1,500X150 - 12T, 15T, 18T MDF NC 가공 - LED 간접조명 - 지정 우레탄 도장 마감 | F5: EA | G5: 1 | H5: 5400000
D6: Micro RGB 포디움 | E6: [집기 제작] - 3,200X700X500 - 12T, 15T, 18T MDF NC 가공 - 점검도어 경첩(자석) 하드웨어 - 지정 우레탄 도장 마감 | F6: EA | G6: 1 | H6: 4500000
C7: Zone 1 S26 Ultra | D7: 2억화소 테이블-01 | E7: [재활용] - 900X900X100 - 12T, 15T, 18T MDF NC 가공 - 상판 제작 교체 - 지정 필름 마감 | F7: EA | G7: 1 | H7: 1200000
D8: 2억화소 테이블-02 | E8: [재활용] - 900X900X100 - 12T, 15T, 18T MDF NC 가공 - 지정 필름 마감 | F8: EA | G8: 1 | H8: 0
D9: 슈퍼스테디 테이블-01 | E9: [재활용] - 900X900X100 - 12T, 15T, 18T MDF NC 가공 - 상판 제작 교체 - 지정 필름 마감 | F9: EA | G9: 1 | H9: 1200000
D10: 슈퍼스테디 테이블-02 | E10: [재활용] - 900X900X100 - 12T, 15T, 18T MDF NC 가공 - 지정 필름 마감 | F10: EA | G10: 1 | H10: 0
C11: Zone 2 크로스 플랫폼 | D11: 크로스 플랫폼 테이블-01 | E11: [집기 제작] - 3,000X600X900 - 12T, 15T, 18T MDF NC 가공 - 점검도어 경첩(자석) 하드웨어 - 2도 우레탄 도장 마감 | F11: EA | G11: 1 | H11: 3860000
D12: 크로스 플랫폼 테이블-02 | E12: [집기 제작] - 3,200X450X500 - 12T, 15T, 18T MDF NC 가공 - 점검도어 경첩(자석) 하드웨어 - 지정 우레탄 도장 마감 | F12: EA | G12: 1 | H12: 5000000
D13: 크로스 플랫폼 테이블-03 | E13: [집기 제작] - 5,000X600X900 - 12T, 15T, 18T MDF NC 가공 - 점검도어 경첩(자석) 하드웨어 - 2도 우레탄 도장 마감 | F13: EA | G13: 1 | H13: 6400000
D14: 크로스 플랫폼 소파 | E14: [재활용] - 1,630X500X690 - 지정 필름 마감 교체 | F14: EA | G14: 1 | H14: 600000
D15: 크로스 플랫폼 선반-01 | E15: [집기 제작] - 1,860X500X150 - 9T, 15T MDF NC 가공 - 점검도어 경첩(자석) 하드웨어 - 지정 우레탄 도장 마감 | F15: EA | G15: 1 | H15: 1500000
D16: 크로스 플랫폼 선반-02 | E16: [집기 제작] - 1,400X350X35 - 9T, 15T MDF NC 가공 - 지정 우레탄 도장 마감 | F16: EA | G16: 1 | H16: 500000
D17: 크로스 플랫폼 노트북 거치대 | E17: [집기 제작] - 500X350X80 - 18T MDF NC 가공 - 지정 우레탄 도장 마감 | F17: EA | G17: 2 | H17: 340000
D18: 피규어 쇼케이스 (크라운리스) | E18: [집기 제작] - 510X400X540 - 12T, 15T, 18T MDF NC 가공 - 5T 투명아크릴 BOX - 지정 우레탄 도장 마감 | F18: EA | G18: 1 | H18: 540000
D19: 피규어 쇼케이스 (파수인) | E19: [집기 제작] - 300X300X520 - 12T, 15T, 18T MDF NC 가공 - 5T 투명아크릴 BOX - 지정 우레탄 도장 마감 | F19: EA | G19: 1 | H19: 470000
D20: 핸즈온 테이블 | E20: [재활용] - 500X300X690 - 18T MDF NC 가공 - 9T 레이저 가공 (보수 - 하부 금속베이스 제작) - 상판 제작 - 지정 우레탄 도장 마감 | F20: EA | G20: 6 | H20: 1800000
D21: 핸즈온 스툴 | E21: [재활용] - 430X350X450 - 기성 하늘색 가구 | F21: EA | G21: 6 | H21: 0
D22: XR 소파 | E22: [재활용] - 750X600X780 사이드모듈 - 600X600X780 코너모듈 - 삼성강남 소파 | F22: EA | G22: 3 | H22: 0
D23: XR 트레이 | E23: [집기 제작] - 320X380X12 - 3T, 12T 발크로멧(칼라MDF) NC 가공 - 지정 인조가죽, 우레탄 도장 마감 | F23: EA | G23: 3 | H23: 780000
C24: Zone 3 시청각 경험 | D24: 버즈 청음 테이블 | E24: [재활용] - 1,800X900X100 - 15T, 18T MDF NC 가공 - 상판 제작 교체 - 필름마감 | F24: EA | G24: 2 | H24: 3600000
D25: 더 프리스타일 테이블 | E25: [재활용] - 미디어데이 더 프리스타일 테이블 | F25: EA | G25: 2 | H25: 0
C26: Zone 4 갤럭시 AI | D26: AI 라이브쇼 테이블 | E26: [재활용] - 2,650X1,200X750 - 1,935X720X750 - 지정 우레탄 도장 마감 (상판 보수) | F26: EA | G26: 2 | H26: 860000
D27: AI 라이브쇼 스툴 | E27: [재활용] - Ø430*H420 - 홍대 라이브쇼 스툴 | F27: EA | G27: 20 | H27: 0
C28: 베뉴 전반 | D28: 제작집기 반입/설치 | E28: [제작집기 반입] - 2.5톤 1대 4월 6일 (삼성강남->경기광주) - 3.5톤 1대, 1톤 2대 4월 13일 (평택창고->경기광주) - 1톤 1대 4월 17일 (삼성강남->경기광주) - 3.5톤 1대, 1톤 2대 4월 20일 (경기광주->코엑스) - 3.5톤 1대, 1톤 2대 4월 21일 (경기광주->코엑스) - 집기 반입, 반출 및 공장 입고 | F28: 대 | G28: 13 | H28: 5800000
E29: [제작집기 셋팅비] - 집기 양중, 집기 배치, 집기 조립 - 현장 셋팅 잡자재 및 공구 사용 | F29: 식 | G29: 1 | H29: 9600000
D30: 제작집기 철거 | E30: [재활용 집기 철거 및 반출] - 집기/ 3.5톤 2대, 1톤 4대 4월24일, 4월 25일 (코엑스->평택창고) - TV/ 3.5톤 1대 4월24일, 4월25일 (코엑스->평택창고) - 잔넬/ 1톤 1대 4월 25일 (코엑스->평택창고) - XR소파/ 1톤 2대 4월 25일 (코엑스->삼성강남) - 집기 반출 현장 철야 작업 - 현장 철거 잡자재 및 공구 사용 - 야간 상차 후 익일 하차 | F30: 대 | G30: 10 | H30: 7200000
E31: [재활용 집기 창고 입고 및 매장 재설치] - 평택 창고 입고 작업 - 삼성강남 XR쇼파 원복 작업 | F31: 식 | G31: 1 | H31: 2600000
C32: 집기 제작 소계 | H32: =SUM(H4:H31) -> 74950000
C33: 집기 제작 합계 | H33: =TRUNC(H32,-3) -> 74950000
B34: 2. 전시 제작 | C34: 베뉴 전반 | D34: 가설 공사 | E34: [주변 보양 및 현장 정리] - 30,000X29,000 - 양중 동선 보양 및 현장 정리정돈 (보양자재 포함) - 준공 청소 (설치일 및 오픈 당일) - 현장 주야간 작업 | F34: M2 | G34: =30*29 -> 870 | H34: 6500000
E35: [고소작업 리프트] - 설치: (1일차*8대)+(2일차*8대)+(3일차*4대)=20대 | F35: 대 | G35: 20 | H35: 3000000
D36: 목공사 | E36: [기본 바닥단] - 24,000X23,000 - 9T, 15T 합판 및 MDF NC 가공 - 방염도장 - 제작 및 현장 설치 작업 | F36: M2 | G36: =24*23 -> 552 | H36: 37600000
E37: [기본벽체 구조] - 55,700X5,000 - 30X30각재, 5T, 12T, 15T 합판(라운드합판포함) 및 MDF NC 가공 - 상부 라운드 구조 포함 - 방염도장 - 제작 및 현장 설치 작업 | F37: M2 | G37: =55.7*5 -> 278.5 | H37: 34800000
E41: [슈퍼스테디 벽체] - 6,000X3,000 - 30X30각재, 5T, 12T, 15T 합판 및 MDF NC 가공 - 방염도장 - 템바보드 20mm 지정 색 수성도장 마감 - 제작 및 현장 설치 작업 | F41: M2 | G41: =6*3 -> 18 | H41: 3600000
E42: [슈퍼스테디 천장] - 5,000X1,000 - 30X30각재, 5T, 12T, 15T 합판 및 MDF NC 가공 - 방염도장 - 제작 및 현장 설치 작업 | F42: M2 | G42: =5*1 -> 5 | H42: 700000
E43: [크로스 플랫폼 벽체] - 17,000X3,000 - 30X30각재, 5T, 12T, 15T 합판 및 MDF NC 가공 - 방염도장 - 간접조명 프레임 지정 필름 마감 - 제작 및 현장 설치 작업 | F43: M2 | G43: =17*3 -> 51 | H43: 8160000
E44: [크로스 플랫폼 천장] - 8,100X5,000 - 30X30각재, 5T, 12T, 15T 합판 및 MDF NC 가공 - 방염도장 - 천정 처짐 방지 보강 구조 - 제작 및 현장 설치 작업 | F44: M2 | G44: =8.1*5 -> 40.5 | H44: 5670000
...

Sheet 신규 재활용 비교
B3: 2026 WIS | H3: 2025 WIS
B4: 신규제작 | E4: 재활용 | H4: 신규제작 | K4: 재활용
B5: 집기 | C5: 수량 | D5: 금액 | E5: 집기 | F5: 수량 | G5: 금액 | H5: 집기 | I5: 수량 | J5: 금액 | K5: 집기 | L5: 수량 | M5: 금액
B6: 스페이셜 사이니지 거치대 | C6: 4 | D6: 11200000 | E6: 2억화소 테이블-01 | F6: 1 | G6: 1200000 | H6: 금속 벤치 | I6: 1 | J6: 7240000 | K6: AI Agent Showroom TV Frame | L6: 3 | M6: 900000
B7: Micro RGB 바닥단 | C7: 1 | D7: 5400000 | E7: 2억화소 테이블-02 | F7: 1 | G7: 0 | H7: 원형 테이블 | I7: 2 | J7: 2400000 | K7: 개찰구 모형 | L7: 2 | M7: 280000
B8: Micro RGB 포디움 | C8: 1 | D8: 4500000 | E8: 슈퍼스테디 테이블-01 | F8: 1 | G8: 1200000 | H8: 소파-A | I8: 1 | J8: 5110000 | K8: 금속 선반세트 | L8: 4 | M8: 0
B9: 크로스 플랫폼 테이블-01 | C9: 1 | D9: 3860000 | E9: 슈퍼스테디 테이블-02 | F9: 1 | G9: 0 | H9: 소파-B | I9: 1 | J9: 4899000 | K9: 키트 테이블 | L9: 4 | M9: 680000
B10: 크로스 플랫폼 테이블-02 | C10: 1 | D10: 5000000 | E10: 크로스 플랫폼 소파 | F10: 1 | G10: 600000 | H10: 소파-C | I10: 1 | J10: 4747200 | K10: 키트 테이블 스툴 | L10: 8 | M10: 0
B11: 크로스 플랫폼 테이블-03 | C11: 1 | D11: 6400000 | E11: 핸즈온 테이블 | F11: 6 | G11: 1800000 | H11: School zone 캐비닛 | I11: 1 | J11: 738000 | K11: AI Art Easel | L11: 2 | M11: 0
B12: 크로스 플랫폼 선반-01 | C12: 1 | D12: 1500000 | E12: 핸즈온 스툴 | F12: 6 | G12: 0 | H12: School zone 책상 | I12: 1 | J12: 1680000 | K12: 원형 테이블 | L12: 5 | M12: 0
B13: 크로스 플랫폼 선반-02 | C13: 1 | D13: 500000 | E13: XR 소파 | F13: 3 | G13: 0 | H13: School zone 의자 | I13: 1 | J13: 575000 | K13: 악세서리 금속 거치대 | L13: 1 | M13: 0
B14: 크로스 플랫폼 노트북 거치대 | C14: 2 | D14: 340000 | E14: 버즈 청음 테이블 | F14: 2 | G14: 3600000 | H14: Trip zone 테이블 | I14: 1 | J14: 660000 | K14: 키트 테이블 | L14: 2 | M14: 340000
B15: 피규어 쇼케이스 (크라운리스) | C15: 1 | D15: 540000 | E15: 더 프리스타일 테이블 | F15: 2 | G15: 0 | H15: 핸즈온 테이블 | I15: 1 | J15: 1080000 | K15: 핸즈온 테이블 스툴 | L15: 11 | M15: 2420000
B16: 피규어 쇼케이스 (파수인) | C16: 1 | D16: 470000 | E16: AI 라이브쇼 테이블 | F16: 2 | G16: 860000 | H16: 선반 | I16: 2 | J16: 280000
B17: XR 트레이 | C17: 3 | D17: 780000 | E17: AI 라이브쇼 스툴 | F17: 20 | G17: 0 | H17: 빌트인 가구 | I17: 1 | J17: 730000
H18: 단올림 박스 | I18: 1 | J18: 135000
H19: 키트 테이블 스툴 | I19: 4 | J19: 3000000
H20: D/P 테이블 | I20: 2 | J20: 3940000
H21: 조경박스-A | I21: 1 | J21: 709000
H22: 조경박스-B | I22: 1 | J22: 880000
H23: 조경박스-C | I23: 2 | J23: 1027000
H24: 소파-A | I24: 2 | J24: 8280000
H25: 소파-B | I25: 2 | J25: 6624000
H26: 핸즈온 테이블-A | I26: 1 | J26: 8980000
H27: 핸즈온 테이블-B | I27: 1 | J27: 3020000
H28: 85" TV 프레임 | I28: 1 | J28: 970000
H29: 하드웨어 박스 | I29: 1 | J29: 180000
B30: 합계 | C30: =SUM(C6:C29) -> 18 | D30: =SUM(D6:D29) -> 40490000 | E30: 합계 | F30: =SUM(F6:F29) -> 46 | G30: =SUM(G6:G29) -> 9260000 | H30: 합계 | I30: =SUM(I6:I29) -> 33 | J30: =SUM(J6:J29) -> 67884200 | K30: 합계 | L30: =SUM(L6:L29) -> 42 | M30: =SUM(M6:M29) -> 4620000
B32: 재활용 수량 비율 | C32: =F30/SUM(C30,F30) -> 0.71875 | H32: 재활용 수량 비율 | I32: =L30/SUM(I30,L30) -> 0.56
B33: 총 금액 | C33: =SUM(D30,G30) -> 49750000 | H33: 총 금액 | I33: =SUM(J30,M30) -> 72504200

Sheet 1-3.전시_제작(수정)
B1: 증빙 상세 내역(전시제작_2026 World IT Show)
B3: 구분 | C3: 항목 | D3: 소항목 | E3: 세부내역 | F3: 단위 | G3: 수량 | H3: 금액 | I3: 현장사진
B4: 1. 집기 제작 | C4: Intro | D4: 스페이셜 사이니지 거치대 | E4: [집기 제작] - 1,200X2,100X600 - 1.5T EGI 절곡 및 레이저 가공 - 각파이프 내부보강 - 잠금도어 경첩(자석) 하드웨어 - 지정 분체 도장 마감 | F4: EA | G4: 4 | H4: 11200000
D5: Micro RGB 바닥단 | E5: [집기 제작] - 4,500X1,500X150 - 12T, 15T, 18T MDF NC 가공 - LED 간접조명 - 지정 우레탄 도장 마감 | F5: EA | G5: 1 | H5: 5400000
D6: Micro RGB 포디움 | E6: [집기 제작] - 3,200X700X500 - 12T, 15T, 18T MDF NC 가공 - 점검도어 경첩(자석) 하드웨어 - 지정 우레탄 도장 마감 | F6: EA | G6: 1 | H6: 4500000
C7: Zone 1 S26 Ultra | D7: 2억화소 테이블-01 | E7: [재활용] - 900X900X100 - 12T, 15T, 18T MDF NC 가공 - 상판 제작 교체 - 지정 필름 마감 | F7: EA | G7: 1 | H7: 1200000
D8: 2억화소 테이블-02 | E8: [재활용] - 900X900X100 - 12T, 15T, 18T MDF NC 가공 - 지정 필름 마감 | F8: EA | G8: 1 | H8: 0
D9: 슈퍼스테디 테이블-01 | E9: [재활용] - 900X900X100 - 12T, 15T, 18T MDF NC 가공 - 상판 제작 교체 - 지정 필름 마감 | F9: EA | G9: 1 | H9: 1200000
D10: 슈퍼스테디 테이블-02 | E10: [재활용] - 900X900X100 - 12T, 15T, 18T MDF NC 가공 - 지정 필름 마감 | F10: EA | G10: 1 | H10: 0
C11: Zone 2 크로스 플랫폼 | D11: 크로스 플랫폼 테이블-01 | E11: [집기 제작] - 3,000X600X900 - 12T, 15T, 18T MDF NC 가공 - 점검도어 경첩(자석) 하드웨어 - 2도 우레탄 도장 마감 | F11: EA | G11: 1 | H11: 3860000
D12: 크로스 플랫폼 테이블-02 | E12: [집기 제작] - 3,200X450X500 - 12T, 15T, 18T MDF NC 가공 - 점검도어 경첩(자석) 하드웨어 - 지정 우레탄 도장 마감 | F12: EA | G12: 1 | H12: 5000000
D13: 크로스 플랫폼 테이블-03 | E13: [집기 제작] - 5,000X600X900 - 12T, 15T, 18T MDF NC 가공 - 점검도어 경첩(자석) 하드웨어 - 2도 우레탄 도장 마감 | F13: EA | G13: 1 | H13: 6400000
D14: 크로스 플랫폼 소파 | E14: [재활용] - 1,630X500X690 - 지정 필름 마감 교체 | F14: EA | G14: 1 | H14: 600000
D15: 크로스 플랫폼 선반-01 | E15: [집기 제작] - 1,860X500X150 - 9T, 15T MDF NC 가공 - 점검도어 경첩(자석) 하드웨어 - 지정 우레탄 도장 마감 | F15: EA | G15: 1 | H15: 1500000
D16: 크로스 플랫폼 선반-02 | E16: [집기 제작] - 1,400X350X35 - 9T, 15T MDF NC 가공 - 지정 우레탄 도장 마감 | F16: EA | G16: 1 | H16: 500000
D17: 크로스 플랫폼 노트북 거치대 | E17: [집기 제작] - 500X350X80 - 18T MDF NC 가공 - 지정 우레탄 도장 마감 | F17: EA | G17: 2 | H17: 340000
D18: 피규어 쇼케이스 (크라운리스) | E18: [집기 제작] - 510X400X540 - 12T, 15T, 18T MDF NC 가공 - 5T 투명아크릴 BOX - 지정 우레탄 도장 마감 | F18: EA | G18: 1 | H18: 540000
D19: 피규어 쇼케이스 (파수인) | E19: [집기 제작] - 300X300X520 - 12T, 15T, 18T MDF NC 가공 - 5T 투명아크릴 BOX - 지정 우레탄 도장 마감 | F19: EA | G19: 1 | H19: 470000
D20: 핸즈온 테이블 | E20: [재활용] - 500X300X690 - 18T MDF NC 가공 - 9T 레이저 가공 (보수 - 하부 금속베이스 제작) - 상판 제작 - 지정 우레탄 도장 마감 | F20: EA | G20: 6 | H20: 1800000
D21: 핸즈온 스툴 | E21: [재활용] - 430X350X450 - 기성 하늘색 가구 | F21: EA | G21: 6 | H21: 0
D22: XR 소파 | E22: [재활용] - 750X600X780 사이드모듈 - 600X600X780 코너모듈 - 삼성강남 소파 | F22: EA | G22: 3 | H22: 0
D23: XR 트레이 | E23: [집기 제작] - 320X380X12 - 3T, 12T 발크로멧(칼라MDF) NC 가공 - 지정 인조가죽, 우레탄 도장 마감 | F23: EA | G23: 3 | H23: 780000
C24: Zone 3 시청각 경험 | D24: 버즈 청음 테이블 | E24: [재활용] - 1,800X900X100 - 15T, 18T MDF NC 가공 - 상판 제작 교체 - 필름마감 | F24: EA | G24: 2 | H24: 3600000
D25: 더 프리스타일 테이블 | E25: [재활용] - 미디어데이 더 프리스타일 테이블 | F25: EA | G25: 2 | H25: 0
C26: Zone 4 갤럭시 AI | D26: AI 라이브쇼 테이블 | E26: [재활용] - 2,650X1,200X750 - 1,935X720X750 - 지정 우레탄 도장 마감 (상판 보수) | F26: EA | G26: 2 | H26: 860000
D27: AI 라이브쇼 스툴 | E27: [재활용] - Ø430*H420 - 홍대 라이브쇼 스툴 | F27: EA | G27: 20 | H27: 0
C28: 베뉴 전반 | D28: 제작집기 반입/설치 | E28: [제작집기 반입] - 2.5톤 1대 4월 6일 (삼성강남->경기광주) - 3.5톤 1대, 1톤 2대 4월 13일 (평택창고->경기광주) - 1톤 1대 4월 17일 (삼성강남->경기광주) - 3.5톤 1대, 1톤 2대 4월 20일 (경기광주->코엑스) - 3.5톤 1대, 1톤 2대 4월 21일 (경기광주->코엑스) - 집기 반입 | F28: 식 | G28: 1 | H28: 5800000
E29: [제작집기 셋팅비] - 집기 양중, 집기 배치, 집기 조립 - 현장 셋팅 잡자재 및 공구 사용 | F29: 식 | G29: 1 | H29: 9600000
C30: 집기 제작 소계 | H30: =SUM(H4:H29) -> 65150000
C31: 집기 제작 합계 | H31: =TRUNC(H30,-3) -> 65150000
B32: 2. 전시 제작 | C32: 베뉴 전반 | D32: 가설 공사 | E32: [주변 보양 및 현장 정리] - 30,000X29,000 - 양중 동선 보양 및 현장 정리정돈 (보양자재 포함) - 준공 청소 (설치일 및 오픈 당일) - 현장 주야간 작업 | F32: M2 | G32: =30*29 -> 870 | H32: 6500000
E33: [고소작업 리프트] - 설치: (1일차*8대)+(2일차*8대)+(3일차*4대)=20대 | F33: 대 | G33: 20 | H33: 3000000
D34: 목공사 | E34: [기본 바닥단] - 24,000X23,000 - 9T, 15T 합판 및 MDF NC 가공 - 방염도장 - 제작 및 현장 설치 작업 | F34: M2 | G34: =24*23 -> 552 | H34: 37600000
E35: [기본벽체 구조] - 55,700X5,000 - 30X30각재, 5T, 12T, 15T 합판(라운드합판포함) 및 MDF NC 가공 - 상부 라운드 구조 포함 - 방염도장 - 제작 및 현장 설치 작업 | F35: M2 | G35: =55.7*5 -> 278.5 | H35: 34800000
E39: [슈퍼스테디 벽체] - 6,000X3,000 - 30X30각재, 5T, 12T, 15T 합판 및 MDF NC 가공 - 방염도장 - 템바보드 20mm 지정 색 수성도장 마감 - 제작 및 현장 설치 작업 | F39: M2 | G39: =6*3 -> 18 | H39: 3600000
E40: [슈퍼스테디 천장] - 5,000X1,000 - 30X30각재, 5T, 12T, 15T 합판 및 MDF NC 가공 - 방염도장 - 제작 및 현장 설치 작업 | F40: M2 | G40: =5*1 -> 5 | H40: 700000
E41: [크로스 플랫폼 벽체] - 17,000X3,000 - 30X30각재, 5T, 12T, 15T 합판 및 MDF NC 가공 - 방염도장 - 간접조명 프레임 지정 필름 마감 - 제작 및 현장 설치 작업 | F41: M2 | G41: =17*3 -> 51 | H41: 8160000
E42: [크로스 플랫폼 천장] - 8,100X5,500 - 30X30각재, 5T, 12T, 15T 합판 및 MDF NC 가공 - 방염도장 - 천정 처짐 방지 보강 구조 - 제작 및 현장 설치 작업 | F42: M2 | G42: =8.1*5.5 -> 44.55 | H42: 5670000
E44: [더 프리스타일 벽체] - 10,000X3,000 - 30X30각재, 5T, 12T, 15T 합판 및 MDF NC 가공 - 방염도장, 지정 수성도장 마감 - 제작 및 현장 설치 작업 | F44: M2 | G44: =10*3 -> 30 | H44: 4800000
E45: [더 프리스타일 천장] - 4,000X3,000 - 30X30각재, 5T, 9T, 15T 합판 및 MDF NC 가공 - 방염도장, 지정 수성도장 마감 - 제작 및 현장 설치 작업 | F45: M2 | G45: =4*3 -> 12 | H45: 1680000
...

Sheet 1-3.전시_제작
B1: 증빙 상세 내역(전시제작_2026 World IT Show)
B3: 구분 | C3: 항목 | D3: 소항목 | E3: 세부내역 | F3: 단위 | G3: 수량 | H3: 금액 | I3: 현장사진
B4: 1. 집기 제작 | C4: Intro | D4: 스페이셜 사이니지 거치대 | E4: [집기 제작] - 1,200X2,100X600 - 1.5T EGI 절곡 및 레이저 가공 - 각파이프 내부보강 - 잠금도어 경첩(자석) 하드웨어 - 지정 분체 도장 마감 | F4: EA | G4: 4 | H4: 11200000
D5: Micro RGB 바닥단 | E5: [집기 제작] - 4,500X1,500X150 - 12T, 15T, 18T MDF NC 가공 - LED 간접조명 - 지정 우레탄 도장 마감 | F5: EA | G5: 1 | H5: 5400000
D6: Micro RGB 포디움 | E6: [집기 제작] - 3,200X700X500 - 12T, 15T, 18T MDF NC 가공 - 점검도어 경첩(자석) 하드웨어 - 지정 우레탄 도장 마감 | F6: EA | G6: 1 | H6: 4500000
C7: Zone 1 S26 Ultra | D7: 2억화소 테이블-01 | E7: [재활용] - 900X900X100 - 12T, 15T, 18T MDF NC 가공 - 상판 제작 교체 - 지정 필름 마감 | F7: EA | G7: 1 | H7: 1200000
D8: 2억화소 테이블-02 | E8: [재활용] - 900X900X100 - 12T, 15T, 18T MDF NC 가공 - 지정 필름 마감 | F8: EA | G8: 1 | H8: 0
D9: 슈퍼스테디 테이블-01 | E9: [재활용] - 900X900X100 - 12T, 15T, 18T MDF NC 가공 - 상판 제작 교체 - 지정 필름 마감 | F9: EA | G9: 1 | H9: 1200000
D10: 슈퍼스테디 테이블-02 | E10: [재활용] - 900X900X100 - 12T, 15T, 18T MDF NC 가공 - 지정 필름 마감 | F10: EA | G10: 1 | H10: 0
C11: Zone 2 크로스 플랫폼 | D11: 크로스 플랫폼 테이블-01 | E11: [집기 제작] - 3,000X600X900 - 12T, 15T, 18T MDF NC 가공 - 점검도어 경첩(자석) 하드웨어 - 2도 우레탄 도장 마감 | F11: EA | G11: 1 | H11: 3860000
D12: 크로스 플랫폼 테이블-02 | E12: [집기 제작] - 3,200X450X500 - 12T, 15T, 18T MDF NC 가공 - 점검도어 경첩(자석) 하드웨어 - 지정 우레탄 도장 마감 | F12: EA | G12: 1 | H12: 5000000
D13: 크로스 플랫폼 테이블-03 | E13: [집기 제작] - 5,000X600X900 - 12T, 15T, 18T MDF NC 가공 - 점검도어 경첩(자석) 하드웨어 - 2도 우레탄 도장 마감 | F13: EA | G13: 1 | H13: 6400000
D14: 크로스 플랫폼 소파 | E14: [재활용] - 1,630X500X690 - 지정 필름 마감 교체 | F14: EA | G14: 1 | H14: 600000
D15: 크로스 플랫폼 선반-01 | E15: [집기 제작] - 1,860X500X150 - 9T, 15T MDF NC 가공 - 점검도어 경첩(자석) 하드웨어 - 지정 우레탄 도장 마감 | F15: EA | G15: 1 | H15: 1500000
D16: 크로스 플랫폼 선반-02 | E16: [집기 제작] - 1,400X350X35 - 9T, 15T MDF NC 가공 - 지정 우레탄 도장 마감 | F16: EA | G16: 1 | H16: 500000
D17: 크로스 플랫폼 노트북 거치대 | E17: [집기 제작] - 500X350X80 - 18T MDF NC 가공 - 지정 우레탄 도장 마감 | F17: EA | G17: 2 | H17: 340000
D18: 피규어 쇼케이스 (크라운리스) | E18: [집기 제작] - 510X400X540 - 12T, 15T, 18T MDF NC 가공 - 5T 투명아크릴 BOX - 지정 우레탄 도장 마감 | F18: EA | G18: 1 | H18: 540000
D19: 피규어 쇼케이스 (파수인) | E19: [집기 제작] - 300X300X520 - 12T, 15T, 18T MDF NC 가공 - 5T 투명아크릴 BOX - 지정 우레탄 도장 마감 | F19: EA | G19: 1 | H19: 470000
D20: 핸즈온 테이블 | E20: [재활용] - 500X300X690 - 18T MDF NC 가공 - 9T 레이저 가공 (보수 - 하부 금속베이스 제작) - 상판 제작 - 지정 우레탄 도장 마감 | F20: EA | G20: 6 | H20: 1800000
D21: 핸즈온 스툴 | E21: [재활용] - 430X350X450 - 기성 하늘색 가구 | F21: EA | G21: 6 | H21: 0
D22: XR 소파 | E22: [재활용] - 750X600X780 사이드모듈 - 600X600X780 코너모듈 - 삼성강남 소파 | F22: EA | G22: 3 | H22: 0
D23: XR 트레이 | E23: [집기 제작] - 320X380X12 - 3T, 12T 발크로멧(칼라MDF) NC 가공 - 지정 인조가죽, 우레탄 도장 마감 | F23: EA | G23: 3 | H23: 780000
C24: Zone 3 시청각 경험 | D24: 버즈 청음 테이블 | E24: [재활용] - 1,800X900X100 - 15T, 18T MDF NC 가공 - 상판 제작 교체 - 필름마감 | F24: EA | G24: 2 | H24: 3600000
D25: 더 프리스타일 테이블 | E25: [재활용] - 미디어데이 더 프리스타일 테이블 | F25: EA | G25: 2 | H25: 0
C26: Zone 4 갤럭시 AI | D26: AI 라이브쇼 테이블 | E26: [재활용] - 2,650X1,200X750 - 1,935X720X750 - 지정 우레탄 도장 마감 (상판 보수) | F26: EA | G26: 2 | H26: 860000
D27: AI 라이브쇼 스툴 | E27: [재활용] - Ø430*H420 - 홍대 라이브쇼 스툴 | F27: EA | G27: 20 | H27: 0
C28: 베뉴 전반 | D28: 제작집기 반입/설치 | E28: [제작집기 반입] - 2.5톤 1대 4월 6일 (삼성강남->경기광주) - 3.5톤 1대, 1톤 2대 4월 13일 (평택창고->경기광주) - 1톤 1대 4월 17일 (삼성강남->경기광주) - 3.5톤 1대, 1톤 2대 4월 20일 (경기광주->코엑스) - 3.5톤 1대, 1톤 2대 4월 21일 (경기광주->코엑스) - 집기 반입 | F28: 식 | G28: 1 | H28: 5800000
E29: [제작집기 셋팅비] - 집기 양중, 집기 배치, 집기 조립 - 현장 셋팅 잡자재 및 공구 사용 | F29: 식 | G29: 1 | H29: 9600000
C30: 집기 제작 소계 | H30: =SUM(H4:H29) -> 65150000
C31: 집기 제작 합계 | H31: =TRUNC(H30,-3) -> 65150000
B32: 2. 전시 제작 | C32: 베뉴 전반 | D32: 가설 공사 | E32: [주변 보양 및 현장 정리] - 30,000X29,000 - 양중 동선 보양 및 현장 정리정돈 (보양자재 포함) - 준공 청소 (설치일 및 오픈 당일) - 현장 주야간 작업 | F32: M2 | G32: =30*29 -> 870 | H32: 6500000
E33: [고소작업 리프트] - 설치: (1일차*8대)+(2일차*8대)+(3일차*4대)=20대 | F33: 식 | G33: 1 | H33: 3000000
D34: 목공사 | E34: [기본 바닥단] - 24,000X23,000 - 9T, 15T 합판 및 MDF NC 가공 - 방염도장 - 제작 및 현장 설치 작업 | F34: M2 | G34: =24*23 -> 552 | H34: 37600000
E35: [기본벽체 구조] - 55,700X5,000 - 30X30각재, 5T, 12T, 15T 합판(라운드합판포함) 및 MDF NC 가공 - 상부 라운드 구조 포함 - 방염도장 - 제작 및 현장 설치 작업 | F35: M2 | G35: =55.7*5 -> 278.5 | H35: 34800000
E39: [슈퍼스테디 벽체] - 6,000X3,000 - 30X30각재, 5T, 12T, 15T 합판 및 MDF NC 가공 - 방염도장 - 템바보드 20mm 지정 색 수성도장 마감 - 제작 및 현장 설치 작업 | F39: M2 | G39: =6*3 -> 18 | H39: 3600000
E40: [슈퍼스테디 천장] - 5,000X1,000 - 30X30각재, 5T, 12T, 15T 합판 및 MDF NC 가공 - 방염도장 - 제작 및 현장 설치 작업 | F40: M2 | G40: =5*1 -> 5 | H40: 700000
E41: [크로스 플랫폼 벽체] - 17,000X3,000 - 30X30각재, 5T, 12T, 15T 합판 및 MDF NC 가공 - 방염도장 - 간접조명 프레임 지정 필름 마감 - 제작 및 현장 설치 작업 | F41: M2 | G41: =17*3 -> 51 | H41: 8160000
E42: [크로스 플랫폼 천장] - 8,100X5,500 - 30X30각재, 5T, 12T, 15T 합판 및 MDF NC 가공 - 방염도장 - 천정 처짐 방지 보강 구조 - 제작 및 현장 설치 작업 | F42: M2 | G42: =8.1*5.5 -> 44.55 | H42: 5670000
E44: [더 프리스타일 벽체] - 10,000X3,000 - 30X30각재, 5T, 12T, 15T 합판 및 MDF NC 가공 - 방염도장, 지정 수성도장 마감 - 제작 및 현장 설치 작업 | F44: M2 | G44: =10*3 -> 30 | H44: 4800000
E45: [더 프리스타일 천장] - 4,000X3,000 - 30X30각재, 5T, 9T, 15T 합판 및 MDF NC 가공 - 방염도장, 지정 수성도장 마감 - 제작 및 현장 설치 작업 | F45: M2 | G45: =4*3 -> 12 | H45: 1680000
...

Sheet 2-1.키트_요약
E6: (단위: 원)
B7: 브랜드 | C7: 항목 | D7: 청구액 | E7: 비고
B8: 2026 WIS | C8: WIS 키트 | D8: ='2-2.키트'!C6 -> 17559262 | E8: * 시트 WIS 키트 견적서 및 세부 증빙 참고
C9: WIS 컨텐츠/솔루션 | D9: ='2-3.키트_컨텐츠솔루션'!C6 -> 84080926 | E9: * 시트 WIS 컨텐츠 및 솔루션 견적서 및 세부 증빙 참고
C10: WIS 설치 및 철거 | D10: ='2-4.키트_설치 및 철거'!C6 -> 24541790 | E10: * 시트 WIS 설치 및 철거 견적서 및 세부 증빙 참고
B11: 키트 총계 | D11: =SUM(D8:D10) -> 126181978
B12: 총 합계 | D12: =SUM(D11) -> 126181978

Sheet 2-2.키트
B2: 공급받는자 | E2: [ 행사 표준 견적서 ] | T2: 공급하는자
B3: CLIENT | C3: 삼성전자㈜ | E3: 아래와 같이 견적 합니다. | T3: 회사명 | U3: ㈜ 제일기획 | V3: (주) 제일기획
B4: PROJECT | C4: 2026 WIS 삼성전자관 | T4: 대표자 | U4: 김종현 | V4: 김종현
B5: PROJECT No. | T5: 사업자번호 | V5: 202-81-45960
B6: 견적금액 | C6: =S26 -> 17559262 | D6: (VAT별도) | T6: 주소 | V6: 서울시 용산구 한남동 736-1
B7: 담당자/연락처 | C7: 박형석 프로 | T7: 담당자/연락처
B9: 구분 | C9: 항목 | E9: 참여 인력 | P9: 금액 | Q9: 일수 | R9: 수량 | S9: 최종금액 | T9: 증빙 사진
E11: 디자이너 | I11: SW 기술자 | L11: 엔지니어링 기술자
E12: 특급 | F12: 고급 | G12: 중급 | H12: 초급 | I12: 응용 SW개발자 | J12: UI/UX 기획/개발자 | K12: UI/UX 디자이너 | L12: 특급 | M12: 고급 | N12: 중급 | O12: 초급
B15: 제작 | C15: 오디세이 POP 플레이트 | D15: ○ POP 플레이트 - 오디세이G9 POP 플레이트 부착 - 아크릴 화이트 무광처리 인쇄 - 평판 부착형 | P15: 120000 | R15: 3 | S15: =P15*R15 -> 360000
C16: 버즈 키트 | D16: ○ 유선 시건 크래들 교체 하우징 가공 및 마감 공정 - 회수 키트 재활용을 위한 시건줄 장착 및 키트 보수 작업 | P16: 220000 | R16: 6 | S16: =P16*R16 -> 1320000
C17: 핸즈온 키트 [ 세로형 ] Galaxy S26 Ultra | D17: ○ 베이스 - 재활용 - 기존 핸즈온(Hands-on) 몸체의 손상 없는 네임플레이트 정밀 탈거 및 부착면 본딩,양면 제거, 표면 평활화(Sanding) 등 최적의 도장을 위한 기초 표면 처리 - 반투명 화이트 컬러의 특수 조색 진행 및 전체 하우징 도장/코팅 마감 처리를 통한 신규 제품 수준의 퀄리티 제작 ○ 네임플레이트 - 신규제작 ( Galaxy S26 Ultra ) - 투명 아크릴 CNC 머시닝 : 투명 아크릴 소재를 활용하여 오차 범위를 최소화한 지정 규격 정밀 CNC 절삭 및 외곽 가공 - 반투명 S26 히어로 컬러의 특수 조색 진행 및 네임플레이트 도장/코팅 마감 처리, 신규 로고 화이트 1도 실크인쇄 마감 ○ 고속 마그네틱 충전 케이블 및 충전 어댑터 - 구매 - 기존의 파손 및 단자 분실, 고장 케이블 제거 후 신규 충전 케이블 장착 | P17: 400000 | R17: 4 | S17: =P17*R17 -> 1600000
C18: 리모컨 대형 목업 | D18: ○ 리모컨 대형 목업 리터치 - 사이즈: 1600*800*150 - 재료 : abs - 1차 자제 가공 : 레이저 ,cnc가공, mct가공 - 2차: 가공품 사상및 조립 '- 3차 : 제품 도장 (하도 우레탄 도장) - 상도 클리어 - 1도 실크인쇄 '○ 버튼 패드 도장 - 전체 화이트 도장 (하도 우레탄 도장) - 문구 1도 실크인쇄 | P18: 1500000 | R18: 1 | S18: =P18*R18 -> 1500000
D19: ○ 제품 테두리 라인 라이팅 제작 - 사이즈 50*50*4000 - 재료 : 알루미늄 프레임, led스트립,smps등, 무빙 프로그램및 컨트롤러 | P19: 1000000 | R19: 1 | S19: =P19*R19 -> 1000000
C20: ACC 월 | D20: ○ 260 판 X 12ea , 스트랩 고정 핀 - ABS 판 제단 - 후처리 작업(모래센딩) - 지정컬러 도장 - 아크릴 고정부속 제작+ 타공, 나사 작업 | P20: 2945000 | R20: 1 | S20: =P20*R20 -> 2945000
D21: ○ '260 판 X 12ea , 버즈 고정 핀 - ABS 판 제단 - 후처리 작업(모래센딩) - 지정컬러 도장 - 아크릴 고정부속 제작+ 타공, 나사 작업 | P21: 2945000 | R21: 1 | S21: =P21*R21 -> 2945000
D22: ○ 밑판3ea(인조가죽 싸바리) - 워치 스탠드 2ea | P22: 1200000 | R22: 1 | S22: =P22*R22 -> 1200000
C23: 탭 포디움 | D23: ○ 탭 포디움 스크레치, 연결부위 보수 작업 - 재도장 작업을 위한 표면 마감 처리 - 우레탄 스프레이 (자동차 도료) - 우레탄 페인트를 신너 등과 혼합하여 목표(메탈릭 실버) 색상에 도달 - 제품 표면에 균일하게 분사 | P23: 685000 | R23: 3 | S23: =P23*R23 -> 2055000
B24: 총계 | S24: =SUM(S15:S23) -> 14925000
B25: 대행수수료 | S25: =S24*17.65% -> 2634262.5
B26: 대행수수료 포함 총계 | S26: =SUM(S24:S25) -> 17559262

Sheet 2-3.키트_컨텐츠솔루션
B2: 공급받는자 | E2: [ 행사 표준 견적서 ] | U2: 공급하는자
B3: CLIENT | C3: 삼성전자㈜ | E3: 아래와 같이 견적 합니다. | U3: 회사명 | V3: ㈜ 제일기획 | W3: (주) 제일기획
B4: PROJECT | C4: 2026 WIS 삼성전자관 | U4: 대표자 | V4: 김종현 | W4: 김종현
B5: PROJECT No. | U5: 사업자번호 | W5: 202-81-45960
B6: 견적금액 | C6: =T30 -> 84080926 | D6: (VAT별도) | U6: 주소 | W6: 서울시 용산구 한남동 736-1
B7: 담당자/연락처 | C7: 박형석 프로 | U7: 담당자/연락처
B9: 구분 | C9: 항목 | E9: 참여 인력 | Q9: 금액 | R9: 일수 | S9: 수량 | T9: 최종금액 | U9: 증빙 사진 | Y9: 디자이너 (서비스∙경험) 등급별 노임단가 (2026) | AF9: SW기술자 등급별 노임단가 (2026) | AM9: 엔지니어링 기술자 (기계∙설비) 등급별 노임단가 (2026)
Y10: 구분 | Z10: 직접인건비 | AA10: 직접경비 | AB10: 재경비 | AC10: 기술료 | AD10: 최종 수렴 비용 | AF10: 구분 | AG10: 직접인건비 | AH10: 직접경비 | AI10: 재경비 | AJ10: 기술료 | AK10: 최종 수렴 비용 | AM10: 구분 | AN10: 직접인건비 | AO10: 직접경비 | AP10: 재경비 | AQ10: 기술료 | AR10: 최종 수렴 비용
E11: 디자이너 | I11: SW 기술자 | M11: 엔지니어링 기술자 | Y11: 특급 기술자 | Z11: 265163 | AA11: =Z11*10% -> 26516.3 | AB11: =Z11*30% -> 79548.9 | AC11: =(Z11+AB11)*40% -> 137884.76 | AD11: =SUM(Z11:AC11) -> 509112.96 | AF11: 응용SW개발자 | AG11: 378350 | AH11: =AG11*10% -> 37835 | AI11: =AG11*30% -> 113505 | AJ11: =(AG11+AI11)*40% -> 196742 | AK11: =SUM(AG11:AJ11) -> 726432 | AM11: 특급 기술자 | AN11: 401407 | AO11: =AN11*0.1 -> 40140.7 | AP11: =AN11*0.3 -> 120422.1 | AQ11: =(AN11+AP11)*0.4 -> 208731.64 | AR11: =SUM(AN11:AQ11) -> 770701.44
E12: 특급 | F12: 고급 | G12: 중급 | H12: 초급 | I12: 응용 SW개발자 | J12: UI/UX 기획/개발자 | K12: UI/UX 디자이너 | L12: IT PM | M12: 특급 | N12: 고급 | O12: 중급 | P12: 초급 | Y12: 고급 기술자 | Z12: 222309 | AA12: =Z12*10% -> 22230.9 | AB12: =Z12*30% -> 66692.7 | AC12: =(Z12+AB12)*40% -> 115600.68 | AD12: =SUM(Z12:AC12) -> 426833.28 | AF12: UI/UX 기획/개발자 | AG12: 336666 | AH12: =AG12*10% -> 33666.6 | AI12: =AG12*30% -> 100999.8 | AJ12: =(AG12+AI12)*40% -> 175066.32 | AK12: =SUM(AG12:AJ12) -> 646398.72 | AM12: 고급 기술자 | AN12: 335379 | AO12: =AN12*0.1 -> 33537.9 | AP12: =AN12*0.3 -> 100613.7 | AQ12: =(AN12+AP12)*0.4 -> 174397.08 | AR12: =SUM(AN12:AQ12) -> 643927.68
Y13: 중급 기술자 | Z13: 219399 | AA13: =Z13*10% -> 21939.9 | AB13: =Z13*30% -> 65819.7 | AC13: =(Z13+AB13)*40% -> 114087.48 | AD13: =SUM(Z13:AC13) -> 421246.08 | AF13: UI/UX 디자이너 | AG13: 251671 | AH13: =AG13*10% -> 25167.1 | AI13: =AG13*30% -> 75501.3 | AJ13: =(AG13+AI13)*40% -> 130868.92 | AK13: =SUM(AG13:AJ13) -> 483208.32 | AM13: 중급 기술자 | AN13: 300463 | AO13: =AN13*0.1 -> 30046.3 | AP13: =AN13*0.3 -> 90138.9 | AQ13: =(AN13+AP13)*0.4 -> 156240.76 | AR13: =SUM(AN13:AQ13) -> 576888.96
Y14: 초급 기술자 | Z14: 193221 | AA14: =Z14*10% -> 19322.1 | AB14: =Z14*30% -> 57966.3 | AC14: =(Z14+AB14)*40% -> 100474.92 | AD14: =SUM(Z14:AC14) -> 370984.32 | AF14: IT PM | AG14: 492039 | AH14: =AG14*10% -> 49203.9 | AI14: =AG14*30% -> 147611.7 | AJ14: =(AG14+AI14)*40% -> 255860.28 | AK14: =SUM(AG14:AJ14) -> 944714.88 | AM14: 초급 기술자 | AN14: 263602 | AO14: =AN14*0.1 -> 26360.2 | AP14: =AN14*0.3 -> 79080.6 | AQ14: =(AN14+AP14)*0.4 -> 137073.04 | AR14: =SUM(AN14:AQ14) -> 506115.84
B15: 컨텐츠 | C15: 스페이셜 사이니지 | D15: ○ 전체 일정 관리 및 커뮤니케이션 총괄 - 전체 제작 마스터 스케줄 수립 및 단계별 마일스톤 관리 (기획 → 디자인 → 편집 → QA → 납품) - 파트 간 작업 의존성 조율 및 병목 구간 사전 식별·대응 - 납품 포맷·해상도·재생 사양 등 기술 스펙 확인 및 각 파트 공유 - 현장 설치 일정 조율 및 하드웨어 팀과의 납품 체크리스트 관리 | L15: 1 | Q15: =E15*$AD$11+F15*$AD$12+G15*$AD$13+H15*$AD$14+I15*$AK$11+J15*$AK$12+K15*$AK$13+L15*$AK$14+M15*$AR$11+N15*$AR$12+O15*$AR$13+P15*$AR$14 -> 944714.88 | R15: 12 | T15: =ROUNDDOWN(Q15*R15,-4) -> 11330000
D16: ○ AI 팬큐 연출 및 영상 콘셉트/스크립트 기획(UI/UX 기획/개발) - 스페이셜 키오스크 4종 각각의 영상 콘셉트 수립 - AI 생성 휴먼 캐릭터 4종의 페르소나 설정 (성별, 연령대, 톤앤매너, 역할 등) - 영상별 스크립트 작성 및 내레이션·자막 방향 기획, 컨펌 대응 - AI 오브제 및 배경 요소 구성안 작성 및 연출 콘티 제작 - 키오스크 공간 특성(전면 배치, 관람 동선)을 고려한 영상 연출 구조 및 시선 유도 방향 기획 | J16: 2 | Q16: =E16*$AD$11+F16*$AD$12+G16*$AD$13+H16*$AD$14+I16*$AK$11+J16*$AK$12+K16*$AK$13+L16*$AK$14+M16*$AR$11+N16*$AR$12+O16*$AR$13+P16*$AR$14 -> 1292797.4 | R16: 6 | T16: =ROUNDDOWN(Q16*R16,-4) -> 7750000
D17: ○ AI 파이프라인 기반 영상 제작 및 후반 작업(UI/UX 디자이너) - AI 파이프라인(이미지 생성·학습 모델 활용)을 통한 메인 휴먼 4종 제작 및 비주얼 디렉션 - 영상 내 오브젝트·배경·그래픽 요소 디자인 및 브랜드 가이드라인 적용 - 휴먼 및 오브젝트 모션 제작 (AI 기반 애니메이션 툴 활용 포함) 및 영상 편집 - 4종 영상 포맷별 파일 최종 출력 및 키오스크 해상도·비율 최적화 작업 - 사운드 제작·믹싱, 영상과의 싱크 조율 - 스튜디오와 함께 진행하여 사전 양해 후 WIS 한정 특별 단가 적용 | F17: 2 | K17: 5 | Q17: =E17*$AD$11+F17*$AD$12+G17*$AD$13+H17*$AD$14+I17*$AK$11+J17*$AK$12+K17*$AK$13+L17*$AK$14+M17*$AR$11+N17*$AR$12+O17*$AR$13+P17*$AR$14 -> 3269708.2 | R17: 11 | T17: =ROUNDDOWN(Q17*R17,-4) -> 35960000
D18: ○ 스페이셜 사이니지 하드웨어 - [ASUS] NUC14 Performance NUC14SRKU7 + Win11pro - 기타 케이블 및 키보드 관리용 모니터, 라우터 등 일체 | Q18: 1700000 | S18: 1 | T18: =Q18*S18 -> 1700000
C19: 수평 고정 슈퍼스테디 | D19: ○ 컨텐츠 수정(자젼거 ver) - 변경된 콘텐츠 영상 기반 무빙스타일 아이들 및 체험 화면 이미지 변경 작업 - 체험 탭 이미지 변경 작업 및 모션 추가 작업 - 영상 콘텐츠 테스트 작업 및 체험플로우 업데이트 작업 | K19: 1 | Q19: =E19*$AD$11+F19*$AD$12+G19*$AD$13+H19*$AD$14+I19*$AK$11+J19*$AK$12+K19*$AK$13+L19*$AK$14+M19*$AR$11+N19*$AR$12+O19*$AR$13+P19*$AR$14 -> 483208.32 | R19: 4 | T19: =ROUNDDOWN(Q19*R19,-4) -> 1930000
D20: ○ 시스템 업데이트 - 소프트웨어 시스템 업데이트 작업 | I20: 1 | Q20: =E20*$AD$11+F20*$AD$12+G20*$AD$13+H20*$AD$14+I20*$AK$11+J20*$AK$12+K20*$AK$13+L20*$AK$14+M20*$AR$11+N20*$AR$12+O20*$AR$13+P20*$AR$14 -> 726432 | R20: 1 | T20: =ROUNDDOWN(Q20*R20,-4) -> 720000
C21: 존 사이니지/ 탭 컨텐츠/ 기타 | D21: ○ 존 사이니지 그래픽 디자인 작업 - WIS 향 기능별 백그라운드 그래픽 베리에이션 및 비주얼 작업 - 55"TV 컨텐츠 6ea - 43" 더무빙스타일 4ea | K21: 2 | Q21: =E21*$AD$11+F21*$AD$12+G21*$AD$13+H21*$AD$14+I21*$AK$11+J21*$AK$12+K21*$AK$13+L21*$AK$14+M21*$AR$11+N21*$AR$12+O21*$AR$13+P21*$AR$14 -> 966416.64 | R21: 6 | T21: =ROUNDDOWN(Q21*R21,-4) -> 5790000
D22: ○ 탭 포디움 그래픽 디자인 작업 - 스페이셜 사이니지 설명 / Micro RGB(85’’) 설명 안내 문구 - Tab S9 Ultra 3ea | K22: 1 | Q22: =E22*$AD$11+F22*$AD$12+G22*$AD$13+H22*$AD$14+I22*$AK$11+J22*$AK$12+K22*$AK$13+L22*$AK$14+M22*$AR$11+N22*$AR$12+O22*$AR$13+P22*$AR$14 -> 483208.32 | R22: 1 | T22: =ROUNDDOWN(Q22*R22,-4) -> 480000
D23: ○ SNS/서베이 부분 제외 / APK 재빌드 - WIS용 갤럭시 스토어 디자인 수정 - WIS용 2억화소 탭 컨텐츠 (플로우 간소화 변경) | I23: 1 | Q23: =E23*$AD$11+F23*$AD$12+G23*$AD$13+H23*$AD$14+I23*$AK$11+J23*$AK$12+K23*$AK$13+L23*$AK$14+M23*$AR$11+N23*$AR$12+O23*$AR$13+P23*$AR$14 -> 726432 | R23: 1 | T23: =ROUNDDOWN(Q23*R23,-4) -> 720000
C24: 청음존 모바일 AOD 화면 | D24: ○ 청음존 핸즈온 키트 AOD 화면 디자인 - 세로형 핸즈온/ 버즈 핸즈온 배치 3D렌더링 시안 및 설치 도면화 작업 - 모바일 AOD 화면 그래픽 디자인 작업 | E24: 1 | Q24: =E24*$AD$11+F24*$AD$12+G24*$AD$13+H24*$AD$14+I24*$AK$11+J24*$AK$12+K24*$AK$13+L24*$AK$14+M24*$AR$11+N24*$AR$12+O24*$AR$13+P24*$AR$14 -> 509112.96 | R24: 0.75 | T24: =ROUNDDOWN(Q24*R24,-4) -> 380000
C25: 쇼룸 (인터렉션 월 / 라이브쇼 미러링) | D25: ○ 쇼룸 러닝 인터렉션 월 LED월 규격 변경에 따른 배경 에셋 리사이징 및 재제작 - 화면 비율에 맞춘 레이아웃 재배치 및 해상도 업스케일링 ○ 캐릭터 렌더링 및 비주얼 정합성 최적화 - 바뀐 해상도에서 캐릭터 6종의 외형이 뭉개지거나 왜곡되지 않도록 텍스처 맵핑 최적화 및 렌더링 품질 재조정 | K25: 1 | Q25: =E25*$AD$11+F25*$AD$12+G25*$AD$13+H25*$AD$14+I25*$AK$11+J25*$AK$12+K25*$AK$13+L25*$AK$14+M25*$AR$11+N25*$AR$12+O25*$AR$13+P25*$AR$14 -> 483208.32 | R25: 1 | T25: =ROUNDDOWN(Q25*R25,-4) -> 480000
D26: ○ 시스템 업데이트 - WIS 미디어월 해상도 및 물리적 화면 비율(Aspect Ratio)에 따른 콘텐츠 표시 영역 재설계 - 변경된 디스플레이 사양에 맞춘 모바일-서버-미디어월 간의 데이터 전송 및 출력 규격 재정의 | I26: 1 | Q26: =E26*$AD$11+F26*$AD$12+G26*$AD$13+H26*$AD$14+I26*$AK$11+J26*$AK$12+K26*$AK$13+L26*$AK$14+M26*$AR$11+N26*$AR$12+O26*$AR$13+P26*$AR$14 -> 726432 | R26: 3 | T26: =ROUNDDOWN(Q26*R26,-4) -> 2170000
D27: ○ 쇼룸 인터렉션 하드웨어 - World IT show 인터렉션 PC - 모바일 확인용 모니터 22인치 - PC ↔ 화면 ↔ 모바일용 Wifi 공유기 '○ 쇼룸 미러링 솔루션 하드웨어 - Mini PC 1ea,, HDMI 1ea, HDMI Switch 1ea, 멀티탭 1ea, USB-A to C 1ea, LTE Router 1ea / 일부 재활용 | Q27: 2057000 | S27: 1 | T27: =Q27*S27 -> 2057000
B28: 총계 | T28: =SUM(T15:T27) -> 71467000
B29: 대행수수료 | T29: =T28*17.65% -> 12613926
B30: 대행수수료 포함 총계 | T30: =SUM(T28:T29) -> 84080926

Sheet 2-4.키트_설치 및 철거
B2: 공급받는자 | E2: [ 행사 표준 견적서 ] | T2: 공급하는자
B3: CLIENT | C3: 삼성전자㈜ | E3: 아래와 같이 견적 합니다. | T3: 회사명 | U3: ㈜ 제일기획 | V3: (주) 제일기획
B4: PROJECT | C4: 2026 WIS 삼성전자관 | T4: 대표자 | U4: 김종현 | V4: 김종현
B5: PROJECT No. | T5: 사업자번호 | V5: 202-81-45960
B6: 견적금액 | C6: =S21 -> 24541790 | D6: (VAT별도) | T6: 주소 | V6: 서울시 용산구 한남동 736-1
B7: 담당자/연락처 | T7: 담당자/연락처
B9: 구분 | C9: 항목 | E9: 참여 인력 | P9: 금액 | Q9: 일수 | R9: 수량 | S9: 최종금액 | T9: 증빙 사진 | X9: 디자이너 (서비스∙경험) 등급별 노임단가 (2026) | AE9: SW기술자 등급별 노임단가 (2026) | AL9: 엔지니어링 기술자 (기계∙설비) 등급별 노임단가 (2026)
X10: 구분 | Y10: 직접인건비 | Z10: 직접경비 | AA10: 재경비 | AB10: 기술료 | AC10: 최종 수렴 비용 | AE10: 구분 | AF10: 직접인건비 | AG10: 직접경비 | AH10: 재경비 | AI10: 기술료 | AJ10: 최종 수렴 비용 | AL10: 구분 | AM10: 직접인건비 | AN10: 직접경비 | AO10: 재경비 | AP10: 기술료 | AQ10: 최종 수렴 비용
E11: 디자이너 | I11: SW 기술자 | L11: 엔지니어링 기술자 | X11: 특급 기술자 | Y11: 265163 | Z11: =Y11*10% -> 26516.3 | AA11: =Y11*30% -> 79548.9 | AB11: =(Y11+AA11)*40% -> 137884.76 | AC11: =SUM(Y11:AB11) -> 509112.96 | AE11: 응용SW개발자 | AF11: 378350 | AG11: =AF11*10% -> 37835 | AH11: =AF11*30% -> 113505 | AI11: =(AF11+AH11)*40% -> 196742 | AJ11: =SUM(AF11:AI11) -> 726432 | AL11: 특급 기술자 | AM11: 401407 | AN11: =AM11*0.1 -> 40140.7 | AO11: =AM11*0.3 -> 120422.1 | AP11: =(AM11+AO11)*0.4 -> 208731.64 | AQ11: =SUM(AM11:AP11) -> 770701.44
E12: 특급 | F12: 고급 | G12: 중급 | H12: 초급 | I12: 응용 SW개발자 | J12: UI/UX 기획/개발자 | K12: UI/UX 디자이너 | L12: 특급 | M12: 고급 | N12: 중급 | O12: 초급 | X12: 고급 기술자 | Y12: 222309 | Z12: =Y12*10% -> 22230.9 | AA12: =Y12*30% -> 66692.7 | AB12: =(Y12+AA12)*40% -> 115600.68 | AC12: =SUM(Y12:AB12) -> 426833.28 | AE12: UI/UX 기획/개발자 | AF12: 336666 | AG12: =AF12*10% -> 33666.6 | AH12: =AF12*30% -> 100999.8 | AI12: =(AF12+AH12)*40% -> 175066.32 | AJ12: =SUM(AF12:AI12) -> 646398.72 | AL12: 고급 기술자 | AM12: 335379 | AN12: =AM12*0.1 -> 33537.9 | AO12: =AM12*0.3 -> 100613.7 | AP12: =(AM12+AO12)*0.4 -> 174397.08 | AQ12: =SUM(AM12:AP12) -> 643927.68
X13: 중급 기술자 | Y13: 219399 | Z13: =Y13*10% -> 21939.9 | AA13: =Y13*30% -> 65819.7 | AB13: =(Y13+AA13)*40% -> 114087.48 | AC13: =SUM(Y13:AB13) -> 421246.08 | AE13: UI/UX 디자이너 | AF13: 251671 | AG13: =AF13*10% -> 25167.1 | AH13: =AF13*30% -> 75501.3 | AI13: =(AF13+AH13)*40% -> 130868.92 | AJ13: =SUM(AF13:AI13) -> 483208.32 | AL13: 중급 기술자 | AM13: 300463 | AN13: =AM13*0.1 -> 30046.3 | AO13: =AM13*0.3 -> 90138.9 | AP13: =(AM13+AO13)*0.4 -> 156240.76 | AQ13: =SUM(AM13:AP13) -> 576888.96
X14: 초급 기술자 | Y14: 193221 | Z14: =Y14*10% -> 19322.1 | AA14: =Y14*30% -> 57966.3 | AB14: =(Y14+AA14)*40% -> 100474.92 | AC14: =SUM(Y14:AB14) -> 370984.32 | AE14: IT PM | AF14: 492039 | AG14: =AF14*10% -> 49203.9 | AH14: =AF14*30% -> 147611.7 | AI14: =(AF14+AH14)*40% -> 255860.28 | AJ14: =SUM(AF14:AI14) -> 944714.88 | AL14: 초급 기술자 | AM14: 263602 | AN14: =AM14*0.1 -> 26360.2 | AO14: =AM14*0.3 -> 79080.6 | AP14: =(AM14+AO14)*0.4 -> 137073.04 | AQ14: =SUM(AM14:AP14) -> 506115.84
B15: 설치 및 철거 | C15: 설치 | D15: ○ 컨텐츠, 솔루선, 키트 설치 - 투입 기간 : 4/21 - 총 1매장(식비,유류비,물류비 포함) - 제작 키트 설치 - 설치 키트 : 스페이셜 사이니지 4ea, 탭 포디움 3ea, 프라이버시 디스플레이 쇼케이스 2ea, 2억 화소 2ea, 슈퍼스테디 2ea, 갤럭시 스토어 2ea, VAC존 버튼 킷 1ea, 리모컨 거치대, 리모컨 대형 목업, ACC 월, 포토어시스트 6ea, 버즈 키트 6ea, Miracle 핸즈온 17ea | I15: 2 | L15: 9 | M15: 7 | O15: 1 | P15: =E15*$AC$11+F15*$AC$12+G15*$AC$13+H15*$AC$14+I15*$AJ$11+J15*$AJ$12+K15*$AJ$13+L15*$AQ$11+M15*$AQ$12+N15*$AQ$13+O15*$AQ$14 -> 13402787 | Q15: 1 | S15: =ROUNDDOWN(P15*Q15,-4) -> 13400000
C16: 오픈대기 | D16: ○ 오픈대기 - 투입기간: 4/22 - 오픈 이슈 대응 대기 인원 (VAC 버튼 솔루션 및 키트 전체) | M16: 1 | N16: 1 | P16: =E16*$AC$11+F16*$AC$12+G16*$AC$13+H16*$AC$14+I16*$AJ$11+J16*$AJ$12+K16*$AJ$13+L16*$AQ$11+M16*$AQ$12+N16*$AQ$13+O16*$AQ$14 -> 1220816.6 | Q16: 1 | S16: =ROUNDDOWN(P16*Q16,-4) -> 1220000
C17: 무선시건 | D17: ○ 무선시건 설치 - 투입 기간 : 4/21 | L17: 1 | M17: 1 | P17: =E17*$AC$11+F17*$AC$12+G17*$AC$13+H17*$AC$14+I17*$AJ$11+J17*$AJ$12+K17*$AJ$13+L17*$AQ$11+M17*$AQ$12+N17*$AQ$13+O17*$AQ$14 -> 1414629.1 | Q17: 1 | S17: =ROUNDDOWN(P17*Q17,-4) -> 1410000
C18: 철거 | D18: ○ 컨텐츠, 솔루선, 키트 철거 - 투입기간 : 4/24 - 철거 키트 : 스페이셜 사이니지 4ea, 탭 포디움 3ea, 프라이버시 디스플레이 쇼케이스 2ea, 2억 화소 2ea, 슈퍼스테디 2ea, 갤럭시 스토어 2ea, VAC존 버튼 킷 1ea, 리모컨 거치대, 리모컨 대형 목업, ACC 월, 포토어시스트 6ea, 버즈 키트 6ea, Miracle 핸즈온 17ea | I18: 2 | L18: 10 | O18: 1 | P18: =E18*$AC$11+F18*$AC$12+G18*$AC$13+H18*$AC$14+I18*$AJ$11+J18*$AJ$12+K18*$AJ$13+L18*$AQ$11+M18*$AQ$12+N18*$AQ$13+O18*$AQ$14 -> 9665994.2 | Q18: 0.5 | S18: =ROUNDDOWN(P18*Q18,-4) -> 4830000
B19: 총계 | S19: =SUM(S15:S18) -> 20860000
B20: 대행수수료 | S20: =S19*17.65% -> 3681790
B21: 대행수수료 포함 총계 | S21: =SUM(S19:S20) -> 24541790

Sheet 3-1.운영
B1: 2026 World IT Show 삼성전자관 운영 청구서
K3: ( 단위 : KRW)
B4: 구분 | C4: 항목 | D4: 구성 | E4: 단위 | F4: 수량 | G4: 일 | H4: 사전견적 | I4: 거래가격 | J4: 차액 | K4: 비고
B5: 공통 | C5: 기획비 | D5: 행사 운영 기획비 | E5: 식 | F5: 1 | G5: 1 | H5: 5000000 | I5: 5000000 | J5: =I5-H5 -> 0 | K5: ○ 제안서 기획, 실행계획 및 운영매뉴얼 작성 | L5: - 25 WIS 4백만 / 25 KES 5백만 - 어떤 내용으로 발생된 금액인지 상세 설명 요청드립니다. > 저희가 부담해야하는 사유 설명 (스튜디오와 동일) - 금액 청구 기준도 확인 必 (인건비 베이스인지, 작성된 제안서가 있는지) | M5: -25년 KES, 기후박람회 모두 500만원 청구했습니다. 이 비용은 협력사의 운영 매뉴얼 작성, 사전 제품 테스트 및 현장 운영 등 운영사의 인건비 베이스 입니다. 증빙으로 운영안 일부와 인건비 청구 근거 첨부합니다. | N5: 2025 WIS / 2025 KES 동일비용
C6: 소계 (1) | H6: =SUM(H5:H5) -> 5000000 | I6: =SUM(I5:I5) -> 5000000 | J6: =I6-H6 -> 0
B7: 운영 | C7: 인건비 | D7: 팬큐레이터 운영 인건비 | E7: 인 | F7: ='운영_인력 근무표'!D7 -> 22 | G7: ='운영_인력 근무표'!L3 -> 3 | H7: =(((210000+(21000*5))*36)*1)+(((210000+(21000*2))*36)*2) -> 29484000 | I7: ='운영_인건비 단가표'!E12*('운영_인력 근무표'!G7+'운영_인력 근무표'!H7+'운영_인력 근무표'!I7) -> 20171800 | J7: =I7-H7 -> -9312200 | K7: ○ 근무일자 및 시간 - 팬큐레이터 22인 -04/22 1일차 (10.5시간) / 07시-17시30분 -04/23 2일차 (8시간) / 09시30분-17시30분 -04/24 3일차 (8시간) / 09시30분-17시30분
D8: 팬큐레이터 리허설 인건비 | E8: 인 | F8: ='운영_인력 근무표'!D7 -> 22 | G8: ='운영_인력 근무표'!L4 -> 1 | H8: =210000*36 -> 7560000 | I8: ='운영_인건비 단가표'!E12*'운영_인력 근무표'!F7 -> 2283600 | J8: =I8-H8 -> -5276400 | K8: ○ 사전 현장 교육 및 리허설 -04/21 교육 및 리허설 (3시간) / 16시-19시
D9: 국문 도슨트 팬큐레이터 운영 인건비 | E9: 인 | F9: ='운영_인력 근무표'!D31 -> 2 | G9: ='운영_인력 근무표'!L3 -> 3 | H9: =(((240000+(24000*5))*2)*1)+(((240000+(24000*2))*2)*2) -> 1872000 | I9: ='운영_인건비 단가표'!E16*('운영_인력 근무표'!G31+'운영_인력 근무표'!H31+'운영_인력 근무표'!I31) -> 2178000 | J9: =I9-H9 -> 306000 | K9: ○ 근무일자 및 시간 - 국문 도슨트 2인 -04/22 1일차 (10.5시간) / 07시-17시30분 -04/23 2일차 (8.5시간) / 09시-17시30분 -04/24 3일차 (8.5시간) / 09시-17시30분 * 4/23 국가 AI전략위, 4/24 방통위 VIP 건으로 인한 조기 출근(9시)으로 인건비 추가 | L9: - 0.5시간 추가된 내역들(국문도슨트 등) 오른쪽 붉은글씨를 비고 아래에도 추가해주세요 | M9: - 추가 완료 | N9: 4/23 국가 AI전략위, 4/24 방통위 VIP 건으로 인한 조기 출근(9시)으로 비용 추가
D10: 국문 도슨트 팬큐레이터 리허설 인건비 | E10: 인 | F10: ='운영_인력 근무표'!D31 -> 2 | G10: ='운영_인력 근무표'!L4 -> 1 | H10: =240000*2 -> 480000 | I10: ='운영_인건비 단가표'!E16*'운영_인력 근무표'!F31 -> 237600 | J10: =I10-H10 -> -242400 | K10: ○ 사전 현장 교육 및 리허설 - 4/21 국문 사전 리허설 (3시간) / 16시-19시
D11: 영문 도슨트 팬큐레이터 운영 인건비 | E11: 인 | F11: ='운영_인력 근무표'!D35 -> 2 | G11: ='운영_인력 근무표'!L3 -> 3 | H11: =(((270000+(27000*5))*2)*1)+(((270000+(27000*2))*2)*2) -> 2106000 | I11: ='운영_인건비 단가표'!E14*('운영_인력 근무표'!G35+'운영_인력 근무표'!H35+'운영_인력 근무표'!I35) -> 2358500 | J11: =I11-H11 -> 252500 | K11: ○ 근무일자 및 시간 - 영문 도슨트 2인 -04/22 1일차 (10.5시간) / 07시-17시30분 -04/23 2일차 (8시간) / 09시30분-17시30분 -04/24 3일차 (8시간) / 09시30분-17시30분
D12: 영문 도슨트 팬큐레이터 리허설 인건비 | E12: 인 | F12: ='운영_인력 근무표'!D31 -> 2 | G12: ='운영_인력 근무표'!L4 -> 1 | H12: =270000*2 -> 540000 | I12: ='운영_인건비 단가표'!E14*'운영_인력 근무표'!F35 -> 267000 | J12: =I12-H12 -> -273000 | K12: ○ 사전 현장 교육 및 리허설 -04/21 교육 및 리허설 (3시간) / 16시-19시
D13: 슈퍼바이저 운영 인건비 | E13: 인 | F13: ='운영_인력 근무표'!D39 -> 6 | G13: ='운영_인력 근무표'!L3 -> 3 | H13: =(((160000+(16000*5))*2)*1)+(((160000+(16000*2))*2)*2) -> 1248000 | I13: =('운영_인건비 단가표'!E21*'운영_인력 근무표'!D39*'운영_인력 근무표'!G40)+('운영_인력 근무표'!D39*'운영_인력 근무표'!H40*'운영_인건비 단가표'!E21)+('운영_인력 근무표'!D39*'운영_인력 근무표'!I40*'운영_인건비 단가표'!E21) -> 4831200 | J13: =I13-H13 -> 3583200 | K13: ○ 근무일자 및 시간 - 슈퍼바이저 6인 -04/22 1일차 (11시간) / 07시-18시 -04/23 2일차 (9시간) / 09시-18시 -04/24 3일차 (10.5시간) / 08시30분-19시 *4/24 방통위 VIP건으로 인한 조기 오픈 세팅 인건비 비용 추가 | M13: - 비고 추가 완료 | N13: 4/24 방통위 VIP건으로 인한 조기 오픈 세팅비용 추가
D14: 슈퍼바이저 사전 / 현장 세팅 인건비 | E14: 인 | F14: ='운영_인력 근무표'!D39 -> 6 | G14: ='운영_인력 근무표'!L4 -> 1 | H14: =(((160000+(16000*4))*2)*1)+(((160000+(16000*13))*2)*1)+(((160000+(16000*4))*2)*1)+(100000*2) -> 1832000 | I14: =(COUNTA('운영_인력 근무표'!E40:E41)*'운영_인건비 단가표'!E21*'운영_인력 근무표'!E40)+('운영_인력 근무표'!D39*'운영_인건비 단가표'!E21*'운영_인력 근무표'!F40)+('운영_인력 근무표'!D39*'운영_인건비 단가표'!E20) -> 3081600 | J14: =I14-H14 -> 1249600 | K14: ○ 사전 세팅 -4/20 (11시간) / 10시-21시 ○ 현장 세팅 -4/21 (12시간) / 10시-22시 -현장 세팅 수당 6인 | L14: - 20일 브롤 계정 세팅이 11시간 걸린건가요? 아니면 다른 세팅도 함께 들어간걸까요? > 정확한 20일 사전세팅 시간 확인 필요 | M14: - 사전 세팅 상세 근무 내용 ( 배그, 명조, 쿠키런 세팅 건입니다) -4/20 (11시간) / 10시-21시 : 크로스 플랫폼 제품 사전 수령 및 초기 세팅 (약 1시간 소요) > 갤럭시 S26 U 7대 / 갤럭시 탭 S9+ 2대 / 갤럭시 탭 S11 1대 / 갤럭시 북6 3대 세팅 : 배틀그라운드 PC 버전 클라이언트 설치 및 계정 점검 (약 2시간 소요) > 배틀그라운드 PC 버전 클라이언트 2대 / 슈퍼계정 4개 설치 및 테스트 : 배틀그라운드 모바일 버전 클라이언트 설치 및 계정 점검 (약 1시간 소요) > 배틀그라운드 모바일 버전 클라이언트 2대 / 슈퍼계정 5개 설치 및 테스트 : 명조 PC 버전 클라이언트 설치 및 슈퍼 계정 정상 연동 점검 (약 7시간 소요) > 명조 PC 버전 클라이언트 1대 / 슈퍼 계정 2개 설치 및 테스트 : 명조 모바일버전 클라이언트 APK 설치 및 슈퍼 계정 정상 연동 점검 (약 2시간 소요) > 명조 모바일 버전 클라이언트 2대(모바일1/탭1) / 슈퍼계정 6개 설치 및 테스트 : 쿠키런 : 오븐스매시 슈퍼 계정 정상 연동 점검 (약 1시간 소요) > 쿠키런 모바일 버전 클라이언트 4대 / 슈퍼계정 9개 설치 및 테스트
D15: 운영요원 운영 인건비 | E15: 인 | F15: ='운영_인력 근무표'!D47 -> 11 | G15: ='운영_인력 근무표'!L3 -> 3 | H15: =(12*(10500*8+15750*2)*1)+(12*(10500*8)*1)+(12*(15750*8+21000*3)*1) -> 4662000 | I15: =('운영_인건비 단가표'!E23*'운영_인력 근무표'!D47*'운영_인력 근무표'!M49)+('운영_인건비 단가표'!E23*'운영_인력 근무표'!D47*'운영_인력 근무표'!H48)+('운영_인건비 단가표'!E23*'운영_인력 근무표'!M51*'운영_인력 근무표'!D47)+('운영_인건비 단가표'!E24*'운영_인력 근무표'!D47*'운영_인력 근무표'!N49)+('운영_인건비 단가표'!E24*'운영_인력 근무표'!D47*'운영_인력 근무표'!N51) -> 3385800 | J15: =I15-H15 -> -1276200 | K15: ○ 근무일자 및 시간 - 운영요원 11인 -04/22 1일차 (11시간/휴게 1시간 포함) / 07시-18시 -04/23 2일차 (9시간/휴게 1시간 포함) / 09시-18시 -04/24 3일차 (10시간/휴게 1시간 포함) / 09시-19시 | N15: 4/24 철거시, 운영요원 1시간 연장 근무
D16: 운영요원 사전 세팅 인건비 | E16: 인 | F16: ='운영_인력 근무표'!D47 -> 11 | G16: ='운영_인력 근무표'!L4 -> 1 | H16: =(4*(10500*8+15750*1)*1) -> 399000 | I16: =('운영_인건비 단가표'!E23*'운영_인력 근무표'!D47*'운영_인력 근무표'!M47)+('운영_인력 근무표'!D47*'운영_인력 근무표'!N47*'운영_인건비 단가표'!E24) -> 1485000 | J16: =I16-H16 -> 1086000 | K16: ○ 현장 세팅 -4/21 (12시간/휴게 1시간 포함) / 10시-22시
D17: 팬큐레이터 초상권 | E17: 인 | F17: 2 | G17: 1 | H17: 0 | I17: =F17*G17*'운영_인건비 단가표'!E35 -> 300000 | J17: =I17-H17 -> 300000 | K17: ○ 팬큐레이터 초상권 비용 - 보도자료 촬영 초상권노출 비용
C18: 소계 (2) | H18: =SUM(H7:H17) -> 50183000 | I18: =SUM(I7:I17) -> 40580100 | J18: =I18-H18 -> -9602900
C19: 부대 인건비 | D19: 운영 식대 | E19: 식 | F19: 206 | G19: 1 | H19: =(10*(10000*2)*1)+(13*(10000*3)*1)+(40*(10000*1)*1)+(58*(10000*1)*1)+(18*(10000*1)*1)+(6*(10000*2)*1) -> 1870000 | I19: =(17*(10000*2)*2)+(26*(10000*1)*1)+(17*(10000*1)*2)+(26*(10000*1)*3) -> 2060000 | J19: =I19-H19 -> 190000 | K19: ○ 식비 - 현장 세팅 & 철거 식비 : 04/21, 4/24 총 2일, 슈퍼바이저 6인, 운영요원 11인 (1일2식) - 현장 리허설 식비 : 04/21, 팬큐레이터 26인 (1일1식) - 근무 운영 식비 : 04/22~23 총 2일, 슈퍼바이저 6인, 운영요원 11인 (1일1식), : 04/22~04/24 총 3일, 팬큐레이터 26인 (1일1식) | L19: - 팬큐 26명인데 30으로 기입 (비고란만 오기입 일까요?) - 10000*206으로 일괄 곱해진 현재 수식 대신 10000*[(2*2*18)+(26*1) 식의 확인 쉬운방식으로의 표기 요청드립니다. (위 인건비 표시주신바와 같이) | M19: -[수정완료]죄송합니다. 최종 금액은 변동없으며 인원수 오기입 건입니다 - 수식 수정 완료
D20: 세탁비 | E20: 인 | F20: 37 | G20: 1 | H20: =(12*10000*1) -> 120000 | I20: ='운영_인건비 단가표'!E37*'3-1.운영'!F20 -> 370000 | J20: =I20-H20 -> 250000 | K20: ○ 세탁비 - 팬큐레이터 26인, 운영요원 11인 / 운영 종료 후 세탁비
D21: 이동 교통비 | E21: 인 | F21: 1 | G21: 1 | H21: =(12*10000*1) -> 120000 | I21: ='3-9. 보험 및 진행비'!H14 -> 70100 | J21: =I21-H21 -> -49900 | K21: ○ 이동 택시비 - 26.04.03 한남동(RX) → 서교동(삼성스토어 홍대) / 갤럭시XR 테스트 및 버즈4 수령 - 26.04.09 한남동(RX) → 서교동(삼성스토어 홍대) / 갤럭시XR 및 비전 AI 컴패니언 테스트 - 26.04.15 한남동(RX) → 서초동(삼성 강남) / 미디어데이 답사 및 인계 물자 점검 - 26.04.17 한남동(RX) → 서초동(삼성 강남) / 미디어데이 인계 물자 수령 - 26.04.17 서초동(삼성 강남) → 한남동(RX) / 미디어데이 인계 물자 이동
C22: 소계 (3) | H22: =SUM(H19:H20) -> 1990000 | I22: =SUM(I19:I21) -> 2500100 | J22: =I22-H22 -> 510100
C23: 컨텐츠 | D23: 스크립트 작성 | E23: 식 | F23: 1 | G23: 1 | I23: ='3-3. 운영_컨텐츠'!H12 -> 3500000 | K23: ○ 국문 스크립트 작성 작업 - 총 6종 (Micro RGB / 크로스 플랫폼 / 갤럭시XR / 버즈 청음&꾸미기 / 더프리스타일 / Vision AI) - 5분/10분 VIP 도슨트 버전 | L23: - 증빙 첨부주신 내용이 스크립트 페이지 전체 첨부일까요? (아닐시 보강 요청) - 장당 청구는 물론 아닐듯 하나, 제작 스크립트 페이지수가 준것에 대비/ 전년 WIS KES와 가격 구별이 크게 없어 청구 기준을 여쭈어봅니다! | M23: - 영문 번역 스크립트 증빙 추가합니다. - 장당 청구는 아니고 스크립트는 각 존당 50만원이 기준입니다. 단, VIP 도슨트의 경우 5분/10분 버전 1개존으로 카운팅하여 총 7개존=7종 스크립트 작성 기준
E24: 식 | F24: 1 | G24: 1 | I24: ='3-3. 운영_컨텐츠'!H13 -> 1000000 | K24: ○ 영문 스크립트 번역 작업 - 5분/10분 VIP 도슨트 버전 번역
C25: 소계 (4) | H25: =SUM(H23,H24,#REF!,#REF!,#REF!,#REF!,#REF!) -> #REF! | I25: =I23+I24 -> 4500000 | J25: =I25-H25 -> #REF!
C26: 시스템 | D26: XR 나우웨이팅 시스템 및 메시지 전송 비용 | E26: 식 | F26: 1 | G26: 1 | H26: 268400 | I26: ='3-4. 운영_시스템'!H12+'3-4. 운영_시스템'!H13 -> 362283 | J26: =I26-H26 -> 93883 | K26: ○ 사용기간 - 4/22~4/24 / 3일 | L26: - 나우웨이팅 청구명세서 첨부 바랍니다. | M26: - 원알엑스 거래명세서로 갈음/ 기존 사진 증빙 有
D27: 도슨트 음향 (이동식 스피커) | E27: 식 | F27: 1 | G27: 1 | H27: 12656000 | I27: ='3-4. 운영_시스템'!H14 -> 2860000 | J27: =I27-H27 -> -9796000 | K27: ○ 도슨트 음향 - KANALS 포터블 스피커 2대 / 4일 - 휴대용 기가폰 2대 / 4일 ○ 운송비 - 왕복 물류비 2회 | L27: - 음향 렌탈내역도 거래내역서 첨부 부탁드리겠습니다. - 도슨트 음향 청구 비용 기준도 함께 확인 바랍니다. (렌탈 내역서 내 몇일*어떤장비 렌탈인지 상세한 내용 필요) | M27: - 도슨트 음향 장비 내역 상세 내역 증빙 추가
C28: 소계 (5) | H28: =SUM(H26:H27) -> 12924400 | I28: =SUM(I26:I27) -> 3222283 | J28: =I28-H28 -> -9702117
C29: 제작물 | D29: 체험 안내 POP | E29: 식 | F29: 1 | G29: 1 | H29: 719950 | I29: ='3-5. 운영_제작물'!H14 -> 411500 | J29: =I29-H29 -> -308450 | K29: ○ 고객 체험 안내 POP (5종) : 초상권 안내 2ea : 운영준비중 2ea : AI Live Show 시간표 1ea | L29: - 전년처럼 표로 간단히 구분된 내용도 증빙으로 함께 첨부주시면 좋을 것 같습니다. - 혹시 출력물 비용 상승이 있었을까요? > 마찬가지로 수량대비 비용이 전년과 큰 구별x | M29: - 첨부완료 - 최근 인쇄 원자재(용지, 잉크 등)가격 상승과 출력 공정의 인건비 인상으로 인해 협력업체의 기본 제작 단가가 불가피하게 조정되었습니다.
D30: 팬큐레이터 유니폼 인쇄 | E30: 개 | F30: 32 | G30: 1 | H30: 2702700 | I30: ='3-5. 운영_제작물'!H12 -> 176000 | J30: =I30-H30 -> -2526700 | K30: ○ 팬큐레이터 상의 유니폼[블루 셔츠] 삼성로고 실크 인쇄 비용 -버퍼 포함 32벌
D31: 운영스텝 유니폼 | E31: 개 | F31: 3 | G31: 1 | H31: 643500 | I31: ='3-5. 운영_제작물'!H13 -> 128700 | J31: =I31-H31 -> -514800 | K31: ○ 운영스텝 상의 맨투맨 - 3벌 | N31: 재고분 부족하여 3벌 구매
C32: 소계 (6) | H32: =SUM(H29:H31) -> 4066150 | I32: =SUM(I29:I31) -> 716200 | J32: =I32-H32 -> -3349950
C33: 네트워크 | D33: 행사장 네트워크 구축 및 사용비 | E33: 식 | F33: 1 | G33: 1 | H33: 7040000 | I33: ='3-6. 운영_네트워크'!H12 -> 5650000 | J33: =I33-H33 -> -1390000 | K33: ○ 총 2회선 (유/무선 2개) ○ 04월 19일 / 11:00~14:00(3시간) / SKT 기사 2인, 메인 1인, 서브 1인 ○ 04월 21일 / 24:00~08:00(8시간) / 메인 1인. 서브 1인, - EPS실 UTP연결 작업 및 회선 OPEN 테스팅 작업 건물 내부 노후화 확인 및 설계 내부 인터넷 선 확인 작업, 회선 포설 위치 계획 작업 내부 벽체 판넬 및 외부 선 진입로 파악, 전시사 협의 - 야간 행사장 부스 각 포인트 UTP 포설 및 매립 작업(내부 철야 작업) UTP 회선 설계 진행 (UTP 작업 : 유선 인테넷을 공유기를 사용 할 수 있도록 무선 회선량 및 회선 분리 작업) - 행사장 부스 포인트에 공유기 간선 및 설치 , UTP 연결 셋팅(내부/외부 철야 작업) - UTP 무선 인터넷 연결 작업 및 효율성 셋팅 셋팅 후 컨트롤에 따라 회선 사용량 한도 조절 및 회선 분배 작업 ○ 04월 22일 / 15:00~21:00(6시간) / 메인 1인, 서브 1인 - 인터넷 연결 테스팅 및 감리 | L33: - 거래명세서 첨부 가능할지 확인 부탁드립니다. - 네트워크 설치는 어떤 업체/어떤분이 진행해주시는 건가요? > 청구 기준 확인이 필요합니다 (사용료일지 설치 인건비일지.) > 사용료는 별도 무선 네트워크 비용을 청구받았기 때문에 / 설치 인력비라면 별도 표기 위해서 더더욱 증빙 필요 | M33: -상세 거래 내역 증빙 첨부 - 유/무선 네트워크 설치를 전문으로하는 업체입니다. 비용 내 항목 하기와 같습니다. - 설치 인건비 (적합 여부 사전 검수, 라인 포설 작업, EPS실 UTP 연결, 회선 설치 작업 등) - 장비 및 자재비 (무선 AP 연결 장비, UTP 케이블, 젠더 등) - 회선 이용료 (네트워크 사용료)
C34: 소계 (7) | H34: =SUM(H33:H33) -> 7040000 | I34: =SUM(I33) -> 5650000 | J34: =I34-H34 -> -1390000
C35: 렌탈 | D35: 휴게 공간 및 현장 운영사무실 물품 렌탈 | E35: 식 | F35: 1 | G35: 1 | H35: 8250000 | I35: ='3-7. 운영_렌탈'!H12 -> 8250000 | J35: =I35-H35 -> 0 | K35: ○ 휴게공간 및 현장 운영사무실 공간조성 물품 렌탈 [렌탈 증빙 시트 참고] - 파티션80ea, 테이블35ea, 의자70ea, 행거 6ea, 전신거울2ea, 냉온수기 5식, 쓰레기통 5식 등 ○ 운영 물품 렌탈 - 무전기 20ea, 복합기1ea,, 멀티탭 40ea, 소화기 15ea 등 | L35: - 마찬가지로 내역서 있으시면 첨부 바랍니다. - 증빙 시트에도 렌탈물품들 수량 측면과 동일하게 기재 바랍니다. > 상사한 렌탈 물품/수량이 깅비된 거래내역서 필요 | M35: 상세 거래 내역 증빙 첨부
C36: 소계 (8) | H36: =SUM(H35:H35) -> 8250000 | I36: =SUM(I35:I35) -> 8250000 | J36: =I36-H36 -> 0
C37: 운영 물품 및 물류 | D37: 설치 / 세팅 물자 운송비 | E37: 식 | F37: 1 | G37: 1 | H37: 330000 | I37: ='3-8. 운영_구매&운송'!H17 -> 590000 | J37: =I37-H37 -> 260000 | K37: ○ 베뉴 세팅 물자(세팅 제품, 운영물자) 운송비 총 12건 | L37: - 구매 영수증 첨부 바랍니다. (원가 추정 해당내용 X)
D38: 운영 물품 구입비 | E38: 식 | F38: 1 | G38: 1 | H38: =3000*32*3 -> 288000 | I38: ='3-8. 운영_구매&운송'!H12+'3-8. 운영_구매&운송'!H13 -> 299990 | K38: ○ 운영 소모품 구입 - 04.22~04.24 / 3일 사용 물품 구매 - 제품닦이 융, 가그린 750ml, 스트랩실, 섬유탈취제, 테이프클리너, 물티슈, 마른걸레, 먼지 제거제 스프레이, 3M 양면테이프, 박스테이프, 모서리캡, 비상약, 계수기 등 ○ 노트북 보호캡 - USB 포트 봉인용 보호캡 구매
D39: 콘솔 컨트롤러 | E39: 식 | F39: 0 | G39: 0 | H39: =3000*2640 -> 7920000 | I39: ='3-8. 운영_구매&운송'!H14 -> 65670 | K39: ○ 크로스 플랫폼존 콘솔 컨트롤러 구매 - 콘트롤러 1대 구입 | M39: 원알엑스 거래명세서로 갈음/ 기존 사진 증빙 有
D40: 버즈 꾸미기 스티커 | E40: 장 | F40: 450 | G40: 1 | H40: 0 | I40: ='3-8. 운영_구매&운송'!H16 -> 870100 | J40: ○ 버즈 커스텀 체험용 꾸미기 스티커 구매 비용 | K40: ○ 버즈 커스텀 체험용 꾸미기 스티커 구매 비용 : 이니셜 스티커 250ea : 꾸미기 스티커 150ea ; 테이프 스티커 9ea : 3D 에폭시 스티커 50ea : 미니 데코 스티커 150ea
D41: 버즈 커스텀 용품 | E41: 식 | F41: 1 | G41: 1 | H41: =3000*2640 -> 7920000 | I41: ='3-8. 운영_구매&운송'!H15 -> 81990 | K41: ○ 버즈 커스텀 테이블 매트 및 스티커 배치 트레이 & 핀셋 구매
...

Sheet 운영_기획료
B1: 거래명세서 (기획료)
B2: 공급받는자(위탁자) | F2: [ 행사 표준 견적서 ] | J2: 공급자(수탁자)
B3: 회사명 | C3: ㈜제일기획 | F3: 아래와 같이 견적 합니다. [ 산출물: 제작결과물 ] | J3: 회사명 | L3: 원리테일익스페리언스코리아리미티드(영업소)
B4: Job Name | C4: 2026 삼성전자 World IT Show 운영 | J4: 대표자 | L4: 김동진
B5: Job | C5: K2S26915001 | J5: 사업자번호 | L5: 839-84-00015
B6: 거래가격 | C6: =F14 -> 5000000 | E6: (VAT별도) | J6: 주소 | L6: 서울시 강남구 학동로 105, 3층(논현동, 제이빌딩)
B7: 담당자/연락처 | C7: 허진영 프로 | J7: 담당자/연락처 | L7: 문정기 프로
B9: 내역 | F9: 합계 | G9: 6월 청구
B10: 부문 | C10: 항목 | D10: 소항목 | E10: 세부내역 | G10: 금액 | H10: 단가 | I10: 인원 | J10: 수량 (개월) | K10: 투입율 | L10: 비고
B11: 2026 삼성전자 World IT Show 기획/운영 | C11: 사전기획 및 현장 운영 관리 | D11: 기획/운영료 | E11: 2026 삼성전자 World IT Show 기획 및 운영 | F11: =SUM(G11) -> 3026982.4 | G11: =H11*I11*J11*K11 -> 3026982.4 | H11: =3783728*2 -> 7567456 | I11: 1 | J11: 2 | K11: 0.2 | L11: 책임연구원 1명 참여율 20% / 2026년도 학술용역단가 기준
E12: 2026 삼성전자 World IT Show 기획 및 운영 | F12: =SUM(G12) -> 2321049.6 | G12: =H12*I12*J12*K12 -> 2321049.6 | H12: =2901312*2 -> 5802624 | I12: 2 | J12: 2 | K12: 0.1 | L12: 연구원 2명 참여율 10% / 2026년도 학술용역단가 기준
C13: 기획료 소계 | F13: =SUM(F11:F12) -> 5348032 | G13: =SUM(G11:G12) -> 5348032
B14: 총계 | F14: =TRUNC(G13,-6) -> 5000000 | G14: =SUM(G13) -> 5348032
F16: 순서 | G16: 구분 | L16: 업무
F17: 1 | G17: 책임연구원 1명 | L17: - 2026 삼성전자 World IT Show 세부운영안 작성 (03/10~04/20) : 03/10 OT 자료 및 방향성 자료 수령 : 03/11~13 방향성에 따른 타이틀 워딩 제안 작업 : 03/16~03/27 프로그램 별 운영 방안 및 도슨트 운영안 초안 작성 > 고객 체험 Journey 작성 > Micro RGB 체험 프로세스 및 운영 방안 초안 작업 > 2억 화소 체험 프로세스 및 운영 방안 초안 작업 > 슈퍼스테디 체험 프로세스 및 운영 방안 초안 작업 > 크로스플랫폼 체험 프로세스 및 운영 방안 초안 작업 > 갤럭시 XR 체험 프로세스 및 운영 방안 초안 작업 > 갤럭시 XR 구글 맵 서치 & 3D 이미지 변환 체험 FLOW 작업 > 버즈 청음 & 커스텀 체험 프로세스 및 운영 방안 초안 작업 > 더프리스타일 체험 프로세스 및 운영 방안 초안 작업 > 비전 AI 컴패니언 체험 프로세스 및 운영 방안 초안 작업 > AI 라이브 쇼 & AI 포토 어시스트 체험 프로세스 및 운영 방안 초안 작업 > VIP 도슨트 5분 경험 프로세스 동선 제안 작업 > VIP 도슨트 전관 방송 시스템 제안 작업 > 팬큐레이터 유니폼 제안 작업 > 닷플랜 작업 : 03/28 프로그램 별 운영방안 수정 작업 > 갤럭시 XR 페이스커버 구매 제안 > 버즈 커스텀 꾸미기 재료 (스티커 등) 제안 > 크로스플랫폼 게임 IP별 배치 기기 제안 > 굿즈 별 소진 방안 작업 : 03/29 프로그램 별 운영방안 수정 작업 > 프로그램 개요 페이지 작업 > 갤럭시 XR 체험프로세스 및 사전 예약 방안 작업 : 03/30 프로그램 별 운영방안 수정 작업 > 갤럭시 XR 현장 테스트 결과 반영 (구글맵 서치 & 치지직XR & 3D 이미지 변환) > AI 라이브 쇼 굿즈 수령 프로세스 작업 : 03/31 프로그램 별 운영방안 수정 작업 > 갤럭시 XR 나우웨이팅 활용 방안 제안 작업 > 기타 프로그램 별 피드백 사항 수정 반영 : 04/01 프로그램 별 운영방안 및 세부 운영안 작업 > 크로스플랫폼 갤럭시 스토어 쿠폰 내용 추가 > 기타 프로그램 별 피드백 사항 수정 반영 : 04/02~03 운영계획안 세부 수정 작업 > Intro Highlight Zone (Micro RGB + 프라이버시 디스플레이) 운영 방안 작업 > 그 외 전시안 수정에 따른 동선 및 프로그램 별 운영방안 수정 작업 : 04/06 운영계획안 세부 수정 작업 > 프로그램 별 체험 시간 시뮬레이션 작업 > 스페이셜 사이니지 별 스크립트 작업 > 그 외 프로그램 별 피드백 사항 수정 반영 : 04/07 운영계획안 세부 수정 작업 > 버즈 커스텀용 소품 (케이스&스티커 등) 구매 제안 작업 : 04/09 운영계획안 세부 수정 작업 > 버즈 청음존 음원 제안 > 비전 AI 컴패니언 발화 문구 및 세부 운영안 작업 > 그 외 전시안 수정 및 피드백에 따른 세부 수정 작업 : 04/13 운영안 수정 작업 > 현장 배치용 POP 시안 작업 및 제안 > 크로스플랫폼 게이밍허브 체험용 컨트롤러 구매 제안 > 크로스플랫폼 PC 체험용 헤드셋 및 기타 장비 제안 : 04/14 운영안 수정 작업 > 크로스플랫폼 인소스유출방지방안 제안 작업 : 04/17 운영계획안 세부 수정 작업 > 닷플랜 및 인력 별 R&R 수정 작업 > KPI 측정 방안 제안 > 프로그램 별 제품 리스트 작업 : 04/20 운영계획안 세부 수정 작업 > 피드백에 따른 운영계획안 최종 수정 작업 - 프로그램 별 현장 테스트 및 물자 인계 작업 (03/30~04/20) : 03/30 삼성스토어 홍대 갤럭시 XR 프로그램 테스트 (삼성스토어 홍대) > 구글 맵 서치, 3D 이미지 변환, 치지직 XR, 유튜브 등 갤럭시 XR 제품 테스트 진행 : 03/31 오디세이 G9 미러링 화면 비율 테스트 (삼성스토어 홍대) > 갤럭시 북 활용 배틀그라운드 실행 및 화면 비율 테스트 진행 : 04/03 갤럭시 XR MWC 프로그램 구동 테스트 (삼성스토어 홍대) > 구글 맵 서치 활용 체험 가능한 해외 관광지 확인 : 04/09 비전 AI 컴패니언 테스트 진행 (삼성스토어 홍대) > 컨텐츠(무비/푸드/스포츠) 별 발화 테스트 진행 : 04/10~13 배틀그라운드 PC 정상 구동 테스트 (ONE-RX) > 창고 보관 데스크톱 내 배틀그라운드 설치 및 정상 구동 가능 여부 테스트 진행 : 04/14 배틀그라운드 모바일 마스터 계정 테스트 (ONE-RX) > 수령 마스터 계정 접속 및 정상 구동 여부 테스트 진행 : 04/15 삼성강남 미디어데이 현장 테스트 (삼성강남) > 비전 AI 컴패니언 솔루션 작동 및 발화 현장 테스트 진행 > 더 프리스타일+ 컨텐츠 별 CXP (오토 키스톤, 오토 레벨링) 현장 테스트 진행 > 게이밍 허브 (명조) 설치 및 구동 현장 테스트 진행 : 04/16 명조 : 게더링웨이브 슈퍼 계정 테스트 (ONE-RX) > 모바일, PC 슈퍼계정 접속 가능 여부 및 정상 구동 테스트 진행 : 04/17 무빙스타일 - 갤럭시 XR - 갤럭시 탭 간 미러링 구동 테스트 (삼성스토어 홍대) > 갤럭시 XR 구동 및 갤럭시 탭 Demo APP 실행 중 무빙스타일 동시 미러링 가능 여부 테스트 진행 : 04/17 미디어데이 제품 인계 (삼성 강남) > 미디어 데이 제품 中 WIS 인계 제품 수령 (더 프리스타일3대 / 헤드셋 3대 / 콘솔 컨트롤러 2대) : 04/20 콘솔 컨트롤러 정상 구동 여부 테스트 > 미디어 데이 인계 컨트롤러 제품 활용 게이밍 허브 명조 구동 가능 여부 테스트 진행 - 2026 삼성전자 World IT Show 현장 세팅 및 운영 (04/21~04/24) > 2026 삼성전자 World IT Show 현장 세팅 및 운영 총괄 (프로그램 별 세팅 및 팬큐레이터 관리, KPI 현황 보고 및 현장 관리 총괄) > 운영 기간 내 VIP 도슨트 관리 총괄 (주최측 일정 어레인지, 국/영문 VIP도슨트 운영 등) - 2026 삼성전자 World IT Show 사후 결과 보고 및 정산 (04/27~05/11) : 사후 결과보고 작성 작업 > 주요 KPI 결과 작성 > 행사 총평 및 Lesson Learned 작성 > 미디어 노출 결과 작성 > 프로그램 별 운영 결과 작성 > 도슨트 투어 운영 결과 작성 (VIP 도슨트 투어 주요 반응 및 현장 사진) > 기타 운영 결과 작성 > 타사 부스 운영 사례 작성
