Workbook

Sheet 전시 공통
B1: 증빙 상세 내역(공통_사업장)
B3: 구분 | C3: 항목 | D3: 소항목 | E3: 세부내역 | G3: 인원 | H3: 수량 | I3: 투입률 | J3: 금액 | K3: 비고 | L3: 사진 | M3: 공시된 엔지니어링 업체 노임 단가 기준표
B4: 공간디자인 | C4: 사업장 디자인 개발 | D4: ○1차_프로젝트 총괄, 제안서 기획, 작성(3일) ○2차_각 베뉴별 기본설계, 2D 디자인, 3D 작업(6일) -투시도 작업 및 수정 보완 -사인 그래픽 2D 작업, 수정 보완 -기본 평입면도 ○3차_마감 스펙 제안(3일) | E4: 참여인력 | F4: 특급기술자 | G4: ='(전시 증빙) 인건비 공통'!F5 -> 1 | H4: ='(전시 증빙) 인건비 공통'!G5 -> 12 | I4: ='(전시 증빙) 인건비 공통'!H5 -> 1 | J4: ='(전시 증빙) 인건비 공통'!I5 -> 7652711.3 | K4: ○기간: 2025.06.27 ~ 2025.07.14 (12일) * 25년 엔지니어링 건설 기술자 노임 단가 기준 (직접인건비, 직접경비, 제경비, 기술료 포함) [공간디자인 및 실시설계] 직접경비: 직접인건비의 10% 제경비: 직접인건비의 20% 기술료: (직접인건비+제경비)의 40%
F5: 중급기술자 | G5: ='(전시 증빙) 인건비 공통'!F6 -> 1 | H5: ='(전시 증빙) 인건비 공통'!G6 -> 12 | I5: ='(전시 증빙) 인건비 공통'!H6 -> 1 | J5: ='(전시 증빙) 인건비 공통'!I6 -> 6067222.6
F6: 초급기술자 | G6: ='(전시 증빙) 인건비 공통'!F7 -> 1 | H6: ='(전시 증빙) 인건비 공통'!G7 -> 12 | I6: ='(전시 증빙) 인건비 공통'!H7 -> 1.2 | J6: ='(전시 증빙) 인건비 공통'!I7 -> 5732443
C7: 공간디자인 사업장 소계 | J7: =TRUNC(SUM(J4:J6),-6) -> 19000000
C8: 공간디자인 사업장 합계 | J8: =TRUNC(J7,-6) -> 19000000
B9: 실시 설계 | C9: 수원 사업장 | D9: ○실시 설계(8일) - 인허가 관련 대관 업무 - 현장 정밀 실측 및 컨디션 조사 - 실시설계도 제작 | E9: 참여인력 | F9: 고급기술자 | G9: ='(전시 증빙) 인건비 공통'!F10 -> 1 | H9: ='(전시 증빙) 인건비 공통'!G10 -> 8 | I9: ='(전시 증빙) 인건비 공통'!H10 -> 1 | J9: ='(전시 증빙) 인건비 공통'!I10 -> 4285955.2 | K9: ○기간: 2025.07.03 ~ 2025.07.14 (8일) * 25년 엔지니어링 건설 기술자 노임 단가 기준 (직접인건비, 직접경비, 제경비, 기술료 포함) [공간디자인 및 실시설계] 직접경비: 직접인건비의 10% 제경비: 직접인건비의 20% 기술료: (직접인건비+제경비)의 40%
F10: 중급기술자 | G10: ='(전시 증빙) 인건비 공통'!F11 -> 1 | H10: ='(전시 증빙) 인건비 공통'!G11 -> 8 | I10: ='(전시 증빙) 인건비 공통'!H11 -> 1 | J10: ='(전시 증빙) 인건비 공통'!I11 -> 4044815
C11: 실시설계_수원 사업장 | J11: =TRUNC(SUM(J9:J10),-6) -> 8000000
C12: 기흥 사업장 | D12: ○실시 설계(8일) - 인허가 관련 대관 업무 - 현장 정밀 실측 및 컨디션 조사 - 실시설계도 제작 | E12: 참여인력 | F12: 고급기술자 | G12: ='(전시 증빙) 인건비 공통'!F13 -> 1 | H12: ='(전시 증빙) 인건비 공통'!G13 -> 8 | I12: ='(전시 증빙) 인건비 공통'!H13 -> 1 | J12: ='(전시 증빙) 인건비 공통'!I13 -> 4285955.2 | K12: ○기간: 2025.07.03 ~ 2025.07.14 (8일) * 25년 엔지니어링 건설 기술자 노임 단가 기준 (직접인건비, 직접경비, 제경비, 기술료 포함) [공간디자인 및 실시설계] 직접경비: 직접인건비의 10% 제경비: 직접인건비의 20% 기술료: (직접인건비+제경비)의 40%
F13: 중급기술자 | G13: ='(전시 증빙) 인건비 공통'!F14 -> 1 | H13: ='(전시 증빙) 인건비 공통'!G14 -> 8 | I13: ='(전시 증빙) 인건비 공통'!H14 -> 1 | J13: ='(전시 증빙) 인건비 공통'!I14 -> 4044815
C14: 실시설계_기흥 사업장 | J14: =TRUNC(SUM(J12:J13),-6) -> 8000000
C15: 화성 사업장 | D15: ○실시 설계(8일) - 인허가 관련 대관 업무 - 현장 정밀 실측 및 컨디션 조사 - 실시설계도 제작 | E15: 참여인력 | F15: 고급기술자 | G15: ='(전시 증빙) 인건비 공통'!F16 -> 1 | H15: ='(전시 증빙) 인건비 공통'!G16 -> 8 | I15: ='(전시 증빙) 인건비 공통'!H16 -> 1 | J15: ='(전시 증빙) 인건비 공통'!I16 -> 4285955.2 | K15: ○기간: 2025.07.03 ~ 2025.07.14 (8일) * 25년 엔지니어링 건설 기술자 노임 단가 기준 (직접인건비, 직접경비, 제경비, 기술료 포함) [공간디자인 및 실시설계] 직접경비: 직접인건비의 10% 제경비: 직접인건비의 20% 기술료: (직접인건비+제경비)의 40%
F16: 중급기술자 | G16: ='(전시 증빙) 인건비 공통'!F17 -> 1 | H16: ='(전시 증빙) 인건비 공통'!G17 -> 8 | I16: ='(전시 증빙) 인건비 공통'!H17 -> 1 | J16: ='(전시 증빙) 인건비 공통'!I17 -> 4044815
C17: 실시설계_화성 사업장 | J17: =TRUNC(SUM(J15:J16),-6) -> 8000000
C18: 실시 설계 합계 | J18: =TRUNC(SUM(J11,J14,J17),-6) -> 24000000
B19: 공통_사업장 소계 | J19: =SUM(J8,J18) -> 43000000
B20: 대행수수료 | J20: =J19*17.65% -> 7589500
B21: 공통_사업장 총계 | J21: =SUM(J19:J20) -> 50589500

Sheet (전시 증빙) 인건비 공통
B2: 기획 및 디자인 인건비 금액 기준표
J3: *25년 엔지니어링 기술자 및 SW 기술자 노임 단가 기준
B4: 구분 | C4: 항목 | D4: 세부내역 | E4: 투입률 100% 기준 합계 | F4: 인원 | G4: 수량 | H4: 투입률 | I4: 비용 | J4: 비고 | L4: 구분 | M4: 직접인건비 | N4: 직접경비 | O4: 제경비 | P4: 기술료 | Q4: 최종 방향 금액 | R4: ** <참고자료> 「엔지니어링산업 진흥법」 제31조제2항에 따른 엔지니어링사업의 대가의 기준 "실비정액가산방식"
B5: 공간 디자인 개발 | C5: 사업장 디자인 | D5: 특급 기술자 | E5: =$Q$5 -> 637725.94 | F5: 1 | G5: 12 | H5: 1 | I5: =E5*G5*H5*F5 -> 7652711.3 | J5: 2025.06.27 ~ 2025.07.14 | L5: 특급기술자 | M5: 358273 | N5: =M5*0.1 -> 35827.3 | O5: =M5*0.2 -> 71654.6 | P5: =(M5+O5)*0.4 -> 171971.04 | Q5: =SUM(M5:P5) -> 637725.94 | R5: 직접인건비
D6: 중급 기술자 | E6: =$Q$7 -> 505601.88 | F6: 1 | G6: 12 | H6: 1 | I6: =E6*G6*H6*F6 -> 6067222.6 | L6: 고급기술자 | M6: 300980 | N6: =M6*0.1 -> 30098 | O6: =M6*0.2 -> 60196 | P6: =(M6+O6)*0.4 -> 144470.4 | Q6: =SUM(M6:P6) -> 535744.4 | R6: 직접경비: 직접인건비의 10%
D7: 초급 기술자 | E7: =$Q$8 -> 398086.32 | F7: 1 | G7: 12 | H7: 1.2 | I7: =E7*G7*H7*F7 -> 5732443 | L7: 중급기술자 | M7: 284046 | N7: =M7*0.1 -> 28404.6 | O7: =M7*0.2 -> 56809.2 | P7: =(M7+O7)*0.4 -> 136342.08 | Q7: =SUM(M7:P7) -> 505601.88 | R7: 제경비: 직접인건비의 20%
C8: 소계 | I8: =TRUNC(SUM(I5:I7),-6) -> 19000000 | L8: 초급기술자 | M8: 223644 | N8: =M8*0.1 -> 22364.4 | O8: =M8*0.2 -> 44728.8 | P8: =(M8+O8)*0.4 -> 107349.12 | Q8: =SUM(M8:P8) -> 398086.32 | R8: 기술료: (직접인건비+제경비)의 40%
B9: 공간 디자인 개발비 합계 | I9: =SUM(I8) -> 19000000
B10: 실시설계 | C10: 수원 사업장 | D10: 고급 기술자 | E10: =$Q$6 -> 535744.4 | F10: 1 | G10: 8 | H10: 1 | I10: =E10*F10*G10*H10 -> 4285955.2 | J10: 2025.07.03 ~ 2025.07.14 | L10: 투입률 (근로 100% = 1일 8시간) | N10: ** <참고자료> 「근로기준법」 제56조(연장ㆍ야간 및 휴일 근로)에 따른 투입률 기준 산정 방식, 해당 기준 이내 근로 투입
D11: 중급 기술자 | E11: =$Q$7 -> 505601.88 | F11: 1 | G11: 8 | H11: 1 | I11: =E11*F11*G11*H11 -> 4044815 | L11: 1 | M11: =L11*8 -> 8 | N11: 1 | O11: 주간 근로 | P11: 1일 8시간
C12: 소계 | I12: =TRUNC(SUM(I10:I11),-6) -> 8000000 | L12: 1.2 | M12: =L12*8 -> 9.6 | N12: 1.5 | O12: 연장 근로 | P12: 1일 8시간, 주 40시간(법정근로시간)을 초과하는 근로시간으로 소정근로시간을 초과한 근로 / 통상임금의 100분의 50 이상 가산
C13: 기흥 사업장 | D13: 고급 기술자 | E13: =$Q$6 -> 535744.4 | F13: 1 | G13: 8 | H13: 1 | I13: =E13*F13*G13*H13 -> 4285955.2 | J13: 2025.07.03 ~ 2025.07.14 | N13: 1.5 | O13: 야간 근로 | P13: 오후 10시 ~ 다음날 오전 6시 사이의 근로 / 통상임금의 100분의 50 이상 가산
D14: 중급 기술자 | E14: =$Q$7 -> 505601.88 | F14: 1 | G14: 8 | H14: 1 | I14: =E14*F14*G14*H14 -> 4044815 | N14: 1.75 | O14: 휴일 근로 | P14: 소정근로일이 아닌 휴일(공휴일 포함)에 일한 근로시간 / 8시간 이내의 휴일근로 : 통상임금의 100분의 50 이상 가산, 8시간 초과 휴일근로 : 통상임금의 100분의 100 가산
C15: 소계 | I15: =TRUNC(SUM(I13:I14),-6) -> 8000000
C16: 화성 사업장 | D16: 고급 기술자 | E16: =$Q$6 -> 535744.4 | F16: 1 | G16: 8 | H16: 1 | I16: =E16*F16*G16*H16 -> 4285955.2 | J16: 2025.07.03 ~ 2025.07.14
D17: 중급 기술자 | E17: =$Q$7 -> 505601.88 | F17: 1 | G17: 8 | H17: 1 | I17: =E17*F17*G17*H17 -> 4044815
C18: 소계 | I18: =TRUNC(SUM(I16:I17),-6) -> 8000000
B19: 실시설계 합계 | I19: =SUM(I12,I15,I18) -> 24000000
B21: 공간 디자인 개발 조직도 | C21: 실시설계 조직도
B22: 사업장 | C22: 수원 | D22: 기흥 | E22: 화성
B23: 플레인오디티 | C23: OneRX | D23: OneRX | E23: OneRX
B24: 김O혜 실장_특급 | C24: 김O찬 실장_고급 | D24: 최O훈 팀장_고급 | E24: 이O엽 실장_고급
B25: 마O우 주임_중급 | C25: 양O열 프로_중급 | D25: 유O석 프로_중급 | E25: 박O훈 프로_중급
B26: 김O빈 디자이너_초급

Sheet 1. 수원 사업장
E2: [ 행사 표준 견적서 ] | H2: 공급하는자
B3: CLIENT | C3: 삼성전자㈜ | E3: 아래와 같이 견적 합니다. | H3: 회사명
B4: PROJECT | C4: 2025 삼성전자 한국총괄 모바일IMC FF7 경험마케팅 사업장(수원) | H4: 대표자
B5: PROJECT No. | C5: KRS25A11015 / KRS25A11016 | H5: 사업자번호
B6: 견적금액 | C6: =H54 -> 2.0882816e+08 | D6: (VAT별도) | H6: 주소
B7: 담당자/연락처 | C7: 김지연 프로 / 010-9582-0410 | H7: 담당자/연락처
B11: 구분 | C11: 항목 | D11: 소항목 | E11: 세부내역 | F11: 단위 | G11: 수량 | H11: 금액 | I11: 현장사진
B12: 1. 집기제작 | C12: 폴드존 | D12: AI Multi-tasking 테이블 | E12: [집기제작] - 1,200X600X1,390 - 1.5T SUS H/L 레이저 절곡 및 재단작업, 코너용접 및 연마작업 - 30*30 각파이프 구조 보강 - 지정 32" 터치 모니터 1EA - 분체 도장 / ABS 탭받침대 도장 마감 | F12: EA | G12: 1 | H12: 9000000
D13: 저울 테이블 | E13: [집기제작] - 1,000X650X950 - 12T, 15T, 18T MDF NC 가공 - 1.5T SUS H/L 레이저 절곡 및 재단작업, 코너용접 및 연마작업 - 30*30 각파이프 구조 보강 - 우레탄 도장 마감 | F13: EA | G13: 1 | H13: 12000000
D14: 비교모뉴먼트 백월 | E14: [집기제작] - 2,400X250X2,050 - 2T SUS H/L 레이저 절곡 및 재단작업, 코너용접 및 연마작업 - 30*30 각파이프 구조 보강 - 10*10 각파이프 메지라인+M5 육각 무두볼트 - 5T 사틴아크릴 1,145X2,000 / 5T 광확산 아크릴 2,400X200 | F14: EA | G14: 1 | H14: 30560000
D15: 2억 화소 월 | E15: [집기제작] - 1,200X250X2,050 - 2T SUS H/L 레이저 절곡 및 재단작업, 코너용접 및 연마작업 - 30*30 각파이프 구조 보강 - 후면 2T 갈바 절곡 경첩 도어 타입 - 지정 분체 마감 | F15: EA | G15: 1 | H15: 4359000
D16: 폴드 핸즈온 테이블 | E16: [집기제작] - 2,400X1,700X950 - 2T SUS H/L, 갈바 레이저 절곡 및 재단작업, 코너용접 및 연마작업 - 30*30 각파이프 구조 보강 - 20*20 서스파이프 보강 및 키트 상판 레이저타공 - 쇼케이스 보강대 및 브라켓 제작 - 지정 분체 마감 | F16: EA | G16: 1 | H16: 8960000
C17: 플립존 | D17: 셀피 보태니컬 월 | E17: [집기제작] - 1,210X160X2,050 - 2T 갈바 레이저 절곡 및 재단작업, 코너용접 및 연마작업 - 30*30 각파이프 구조 보강 - 도어 경첩 하드웨어 - 지정 분체 마감 | F17: EA | G17: 1 | H17: 6000000
D18: 플립 셀피 월 | E18: [집기제작] - 1,210X210X2,050 - 2T 갈바 레이저 절곡 및 재단작업, 코너용접 및 연마작업 - 30*30 각파이프 구조 보강 - 도어 경첩 하드웨어 - 지정 분체 마감 | F18: EA | G18: 1 | H18: 4468000
D19: 셀피 프린트 테이블 | E19: [집기제작] - 1,200X400X950 - 1.5T 갈바 레이저 절곡 및 재단작업, 코너용접 및 연마작업 - 30*30 각파이프 구조 보강 - 지정 분체 마감 | F19: EA | G19: 1 | H19: 4375000
D20: 선반 거울 월 | E20: [집기제작] - 1,210X160X2,050 - 2T SUS H/L 레이저 절곡 및 재단작업, 코너용접 및 연마작업 - 30*30 각파이프 구조 보강 - 430X200X20T SUS H/L 선반 / 5T 은경+프레임 - 도어 경첩 하드웨어 - 지정 분체 마감 | F20: EA | G20: 1 | H20: 5348000
D21: 옷걸이 월 | E21: [집기제작] - 1360X320X2050 - 2T SUS H/L 레이저 절곡 및 재단작업, 코너용접 및 연마작업 - 30*30 각파이프 구조 보강 - 1,150X300X670 하부장 - 지정 분체 및 도장 마감 | F21: EA | G21: 1 | H21: 6000000
D22: 플립 핸즈온 테이블 | E22: [집기제작] - 2,400X1,700X950 - 2T SUS H/L, 갈바 레이저 절곡 및 재단작업, 코너용접 및 연마작업 - 30*30 각파이프 구조 보강 - 20*20 서스파이프 보강 및 키트 상판 레이저타공 - 쇼케이스 보강대 및 브라켓 제작 - 지정 분체 마감 | F22: EA | G22: 1 | H22: 8960000
C23: 베뉴 전반 | D23: 복합기 테이블 | E23: [집기제작] - 600X560X1,000 - 2T SUS H/L, 갈바 레이저 절곡 및 재단작업, 코너용접 및 연마작업 - 30*30 각파이프 구조 보강 | F23: EA | G23: 1 | H23: 4569000
D24: 삼성 판매 테이블 | E24: [집기제작] - 1,200X500X1,000 - 2T SUS H/L, 갈바 레이저 절곡 및 재단작업, 코너용접 및 연마작업 - 30*30 각파이프 구조 보강 - 지정 분체 마감 | F24: EA | G24: 1 | H24: 4714000
D25: 패밀리넷 테이블 | E25: [집기제작] - 900X500X1,000 - 2T SUS H/L, 갈바 레이저 절곡 및 재단작업, 코너용접 및 연마작업 - 30*30 각파이프 구조 보강 - 지정 분체 마감 | F25: EA | G25: 1 | H25: 5041000
D26: 삼판, 패밀리넷 의자 | E26: [집기제작] - 450X510X750 - 기성 바스툴 7개 | F26: EA | G26: 7 | H26: 770000
D27: 제작집기 반입/설치 | E27: [제작집기 반입] - 1톤 2대(경기파주->수원, 7월12일) - 3.5톤 1대(경기파주->수원, 7월12일) - 집기 반입 | F27: 식 | G27: 1 | H27: 3200000
E28: [제작집기 셋팅비] - 집기 양중, 집기 배치, 집기 조립 등의 현장 작업 | F28: 식 | G28: 1 | H28: 4300000
C29: 집기 제작 소계 | H29: =SUM(H12:H28) -> 122624000
C30: 집기 제작 합계 | H30: =TRUNC(H29,-3) -> 122624000
B31: 2. 전시 제작 | C31: 베뉴 전반 | D31: 가설 공사 | E31: [주변 보양 및 현장 정리] - 8,100X4,500 - 양중 동선 보양 및 현장 정리정돈 - 준공 청소 - 보양자재 포함 | F31: M2 | G31: =8.1*4.5 -> 36.45 | H31: 5000000
D32: 목공사 | E32: [베뉴 전체 바닥단] - 8,100X4,500 - 15T, 9T MDF NC 가공 - 철야 제작 및 현장 설치 | F32: M2 | G32: =8.1*4.5 -> 36.45 | H32: 8120000
D33: 금속 공사 | E33: [바닥마감대] - 8,100+4,500+8,100+4,500 / 120X28 - 1.5T SUS H/L 절곡 및 용접 가공 - 철야 제작 및 현장 설치 | F33: M | G33: =8.1+4.5+8.1+4.5 -> 25.2 | H33: 14955000
E34: [사이니지 박스 받침대] - 2,400X250X140 - 2T SUS H/L, 레이저 절곡 및 재단작업, 코너용접 및 연마작업 - Ø50 SUS 파이프 용접 - 철야 제작 및 현장 설치 | F34: 식 | G34: 1
D35: 전기 공사 | E35: [분전반 및 배관배선] - F-CV 2.5 / F-CV 4 벽체 및 바닥 전열 배선 - SMPS포함 잡자재 등 | F35: M2 | G35: =8.1*4.5 -> 36.45 | H35: 4200000
E36: [콘센트 및 조명 설치] - 2구산업용노출콘센트 및 멀티콘센트 - 현장 설치
E37: [추가 조명 제작 설치] - 조명 내부 LED 교체 작업 - 현장 설치 | F37: EA | G37: 2 | H37: 940000
D38: 수장 공사 | E38: [기본 바닥 마감] - 8,100X4,500 - 지정 데코타일 마감 - 현장 설치 | F38: M2 | G38: =8.1*4.5 -> 36.45 | H38: 3550000
D39: 그래픽 사인공사 | E39: [셀피존 그래픽] - 1,200X2,000 - 지정 그래픽 실사출력 - 철야 제작 및 현장 설치 | F39: 식 | G39: 1 | H39: 2700000
E40: [5T 아크릴 스카시] - H:150 Galaxy Z Fold7ㅣZ Filp7 검정 도장 - 철야 제작 및 현장 설치 | F40: 식 | G40: 1
E41: [기둥마감] - 기존 기둥 포맥스 부착 후 백색 필름 마감 - 철야 제작 및 현장 설치 | F41: 식 | G41: 1
D42: 영상하드웨어 공사 | E42: [TV 및 모니터 설치] - 32, 55인치 TV 및 모니터 설치(재활용 장비) - 통신, 영상케이블 배선 바닥, 벽체, 집기 포설작업 - 케이블, 잡자재 포함 - 현장 설치 작업 | F42: 식 | G42: 1 | H42: 1000000
D43: 안전 관리 공사 | E43: [안전 관리비] - 안전모, 안전화, 작업조끼, 경광봉, 안전벨트, 사다리아웃트리거, 말비계 낙상방지기 등 안전 장구류 - 불티방지막, 용접우산, 버미글라스, 기계톱날 커버, 글라인드 날커버 - 소화기 및 비상약품 등 | F43: 식 | G43: 1 | H43: 1500000
D44: 철거 공사 | E44: [구조물 철거 및 정리 정돈, 원복] - 구조물 및 집기 철거 작업 - 구조 철거 현장 작업 - 폐기물 처리비 - 철거 잡자재 및 공구사용 | F44: 식 | G44: 1 | H44: 12050000
...

Sheet 2. 기흥 사업장
E2: [ 행사 표준 견적서 ] | H2: 공급하는자
B3: CLIENT | C3: 삼성전자㈜ | E3: 아래와 같이 견적 합니다. | H3: 회사명
B4: PROJECT | C4: 2025 삼성전자 한국총괄 모바일IMC FF7 경험마케팅 사업장(기흥) | H4: 대표자
B5: PROJECT No. | C5: KRS25A11015 / KRS25A11016 | H5: 사업자번호
B6: 견적금액 | C6: =H53 -> 1.9043765e+08 | D6: (VAT별도) | H6: 주소
B7: 담당자/연락처 | C7: 김지연 프로 / 010-9582-0410 | H7: 담당자/연락처
B11: 구분 | C11: 항목 | D11: 소항목 | E11: 세부내역 | F11: 단위 | G11: 수량 | H11: 금액 | I11: 현장사진
B12: 1. 집기제작 | C12: 폴드존 | D12: AI Multi-tasking 테이블 | E12: [집기제작] - 1,200X600X1,390 - 1.5T SUS H/L 레이저 절곡 및 재단작업, 코너용접 및 연마작업 - 30*30 각파이프 구조 보강 - 지정 32" 터치 모니터 1EA - 분체 도장 / ABS 탭받침대 도장 마감 | F12: EA | G12: 1 | H12: 6470000
D13: 저울 테이블 | E13: [집기제작] - 1,000X650X950 - 12T, 15T, 18T MDF NC 가공 - 1.5T SUS H/L 레이저 절곡 및 재단작업, 코너용접 및 연마작업 - 30*30 각파이프 구조 보강 - 우레탄 도장 마감 | F13: EA | G13: 1 | H13: 7102700
D14: 비교모뉴먼트 백월 | E14: [집기제작] - 2,400X250X2,050 - 2T SUS H/L 레이저 절곡 및 재단작업, 코너용접 및 연마작업 - 30*30 각파이프 구조 보강 - 10*10 각파이프 메지라인+M5 육각 무두볼트 - 5T 사틴아크릴 1,145X2,000 / 5T 광확산 아크릴 2,400X200 | F14: EA | G14: 1 | H14: 25560000
D15: 2억 화소 월 | E15: [집기제작] - 1,200X250X2,050 - 2T SUS H/L 레이저 절곡 및 재단작업, 코너용접 및 연마작업 - 30*30 각파이프 구조 보강 - 후면 2T 갈바 절곡 경첩 도어 타입 - 지정 분체 마감 | F15: EA | G15: 1 | H15: 4359000
D16: 폴드 핸즈온 테이블 | E16: [집기제작] - 2,400X1,700X950 - 2T SUS H/L, 갈바 레이저 절곡 및 재단작업, 코너용접 및 연마작업 - 30*30 각파이프 구조 보강 - 20*20 서스파이프 보강 및 키트 상판 레이저타공 - 쇼케이스 보강대 및 브라켓 제작 - 지정 분체 마감 | F16: EA | G16: 1 | H16: 8960000
C17: 플립존 | D17: 셀피 보태니컬 월 | E17: [집기제작] - 1,210X160X2,050 - 2T 갈바 레이저 절곡 및 재단작업, 코너용접 및 연마작업 - 30*30 각파이프 구조 보강 - 도어 경첩 하드웨어 - 지정 분체 마감 | F17: EA | G17: 1 | H17: 4615000
D18: 플립 셀피 월 | E18: [집기제작] - 1,210X210X2,050 - 2T 갈바 레이저 절곡 및 재단작업, 코너용접 및 연마작업 - 30*30 각파이프 구조 보강 - 도어 경첩 하드웨어 - 지정 분체 마감 | F18: EA | G18: 1 | H18: 4468000
D19: 셀피 프린트 테이블 | E19: [집기제작] - 1,200X400X950 - 1.5T 갈바 레이저 절곡 및 재단작업, 코너용접 및 연마작업 - 30*30 각파이프 구조 보강 - 지정 분체 마감 | F19: EA | G19: 1 | H19: 4375000
D20: 선반 거울 월 | E20: [집기제작] - 1,210X160X2,050 - 2T SUS H/L 레이저 절곡 및 재단작업, 코너용접 및 연마작업 - 30*30 각파이프 구조 보강 - 430X200X20T SUS H/L 선반 / 5T 은경+프레임 - 도어 경첩 하드웨어 - 지정 분체 마감 | F20: EA | G20: 1 | H20: 5348000
D21: 옷걸이 월 | E21: [집기제작] - 1360X320X2050 - 2T SUS H/L 레이저 절곡 및 재단작업, 코너용접 및 연마작업 - 30*30 각파이프 구조 보강 - 1,150X300X670 하부장 - 지정 분체 및 도장 마감 | F21: EA | G21: 1 | H21: 4790000
D22: 플립 핸즈온 테이블 | E22: [집기제작] - 2,400X1,700X950 - 2T SUS H/L, 갈바 레이저 절곡 및 재단작업, 코너용접 및 연마작업 - 30*30 각파이프 구조 보강 - 20*20 서스파이프 보강 및 키트 상판 레이저타공 - 쇼케이스 보강대 및 브라켓 제작 - 지정 분체 마감 | F22: EA | G22: 1 | H22: 8960000
C23: 베뉴 전반 | D23: 복합기 테이블 | E23: [집기제작] - 600X560X1,000 - 2T SUS H/L, 갈바 레이저 절곡 및 재단작업, 코너용접 및 연마작업 - 30*30 각파이프 구조 보강 | F23: EA | G23: 1 | H23: 4569000
D24: 삼성 판매 테이블 | E24: [집기제작] - 1,200X500X1,000 - 2T SUS H/L, 갈바 레이저 절곡 및 재단작업, 코너용접 및 연마작업 - 30*30 각파이프 구조 보강 - 지정 분체 마감 | F24: EA | G24: 1 | H24: 4714000
D25: 패밀리넷 테이블 | E25: [집기제작] - 900X500X1,000 - 2T SUS H/L, 갈바 레이저 절곡 및 재단작업, 코너용접 및 연마작업 - 30*30 각파이프 구조 보강 - 지정 분체 마감 | F25: EA | G25: 1 | H25: 5041000
D26: 삼판, 패밀리넷 의자 | E26: [집기제작] - 450X510X750 - 기성 바스툴 7개 | F26: EA | G26: 7 | H26: 770000
D27: 제작집기 반입/설치 | E27: [제작집기 반입] - 1톤 2대(경기파주->기흥, 7월13일) - 3.5톤 1대(경기파주->기흥, 7월13일) - 집기 반입 | F27: 식 | G27: 1 | H27: 3200000
E28: [제작집기 셋팅비] - 집기 양중, 집기 배치, 집기 조립 등의 현장 작업 | F28: 식 | G28: 1 | H28: 4300000
C29: 집기 제작 소계 | H29: =SUM(H12:H28) -> 107601700
C30: 집기 제작 합계 | H30: =TRUNC(H29,-3) -> 107601000
B31: 2. 전시 제작 | C31: 베뉴 전반 | D31: 가설 공사 | E31: [주변 보양 및 현장 정리] - 7,850X4,500 - 양중 동선 보양 및 현장 정리정돈 - 준공 청소 - 보양자재 포함 | F31: M2 | G31: =7.85*4.5 -> 35.325 | H31: 5000000
D32: 목공사 | E32: [베뉴 전체 바닥단] - 7,850X4,500 - 15T, 9T MDF NC 가공 - 철야 제작 및 현장 설치 작업 | F32: M2 | G32: =7.85*4.5 -> 35.325 | H32: 8120000
D33: 금속 공사 | E33: [바닥마감대] - 7,850+4,500+7,850+4,500 / 120X28 - 1.5T SUS H/L 절곡 및 용접 가공 - 철야 제작 및 현장 설치 작업 | F33: M | G33: =7.85+4.5+7.85+4.5 -> 24.7 | H33: 14856000
E34: [사이니지 박스 받침대] - 2,400X250X140 - 2T SUS H/L, 레이저 절곡 및 재단작업, 코너용접 및 연마작업 - Ø50 SUS 파이프 용접 - 철야 제작 및 현장 설치 작업 | F34: 식 | G34: 1
D35: 전기 공사 | E35: [분전반 및 배관배선] - F-CV 2.5 / F-CV 4 벽체 및 바닥 전열 배선 - SMPS포함 잡자재 등 | F35: M2 | G35: =7.85*4.5 -> 35.325 | H35: 4200000
E36: [콘센트 및 조명 설치] - 2구산업용노출콘센트 및 멀티콘센트 - 현장 설치 철야 작업
E37: [추가 조명 제작 설치] - 조명 내부 LED 교체 작업 - 현장 설치 작업 | F37: EA | G37: 2 | H37: 940000
D38: 수장 공사 | E38: [기본 바닥 마감] - 7,850X4,500 - 지정 데코타일 마감 - 현장 설치 작업 | F38: M2 | G38: =7.85*4.5 -> 35.325 | H38: 3550000
D39: 그래픽 사인공사 | E39: [셀피존 그래픽] - 1,200X2,000 - 지정 그래픽 실사출력 - 철야 제작 및 현장 설치 작업 | F39: 식 | G39: 1 | H39: 2200000
E40: [5T 아크릴 스카시] - H:150 Galaxy Z Fold7ㅣZ Filp7 검정 도장 - 철야 제작 및 현장 설치 작업 | F40: 식 | G40: 1
D41: 영상하드웨어 공사 | E41: [TV 및 모니터 설치] - 32, 55인치 TV 및 모니터 설치(재활용 장비) - 통신, 영상케이블 배선 바닥, 벽체, 집기 포설작업 - 케이블, 잡자재 포함 - 현장 설치 작업 | F41: 식 | G41: 1 | H41: 1000000
D42: 안전 관리 공사 | E42: [안전 관리비] - 안전모, 안전화, 작업조끼, 경광봉, 안전벨트, 사다리아웃트리거, 말비계 낙상방지기 등 안전 장구류 - 불티방지막, 용접우산, 버미글라스, 기계톱날 커버, 글라인드 날커버 - 소화기 및 비상약품 등 | F42: 식 | G42: 1 | H42: 1500000
D43: 철거 공사 | E43: [구조물 철거 및 정리 정돈, 원복] - 구조물 및 집기 철거 작업 - 구조 철거 현장 작업 - 폐기물 처리비 - 철거 잡자재 및 공구사용 | F43: 식 | G43: 1 | H43: 12050000
E44: [재활용 집기 현장 철거 및 정리 정돈, 원복] - 5TON 윙바디 1대(기흥->평택) 8월2일 - 집기 반출 현장 작업 - 평택 창고 입고 작업 | F44: 식 | G44: 1
...

Sheet 3. 화성 사업장
E2: [ 행사 표준 견적서 ] | H2: 공급하는자
B3: CLIENT | C3: 삼성전자㈜ | E3: 아래와 같이 견적 합니다. | H3: 회사명
B4: PROJECT | C4: 2025 삼성전자 한국총괄 모바일IMC FF7 경험마케팅 사업장(화성) | H4: 대표자
B5: PROJECT No. | C5: KRS25A11015 / KRS25A11016 | H5: 사업자번호
B6: 견적금액 | C6: =H52 -> 1.8931412e+08 | D6: (VAT별도) | H6: 주소
B7: 담당자/연락처 | C7: 김지연 프로 / 010-9582-0410 | H7: 담당자/연락처
B11: 구분 | C11: 항목 | D11: 소항목 | E11: 세부내역 | F11: 단위 | G11: 수량 | H11: 금액 | I11: 현장사진
B12: 1. 집기제작 | C12: 폴드존 | D12: AI Multi-tasking 테이블 | E12: [집기제작] - 1,200X600X1,390 - 1.5T SUS H/L 레이저 절곡 및 재단작업, 코너용접 및 연마작업 - 30*30 각파이프 구조 보강 - 지정 32" 터치 모니터 1EA - 분체 도장 / ABS 탭받침대 도장 마감 | F12: EA | G12: 1 | H12: 6470000
D13: 저울 테이블 | F13: EA | G13: 1 | H13: 7102700
D14: 비교모뉴먼트 백월 | E14: [집기제작] - 2,400X250X2,050 - 2T SUS H/L 레이저 절곡 및 재단작업, 코너용접 및 연마작업 - 30*30 각파이프 구조 보강 - 10*10 각파이프 메지라인+M5 육각 무두볼트 - 5T 사틴아크릴 1,145X2,000 / 5T 광확산 아크릴 2,400X200 | F14: EA | G14: 1 | H14: 25560000
D15: 2억 화소 월 | E15: [집기제작] - 1,200X250X2,050 - 2T SUS H/L 레이저 절곡 및 재단작업, 코너용접 및 연마작업 - 30*30 각파이프 구조 보강 - 후면 2T 갈바 절곡 경첩 도어 타입 - 지정 분체 마감 | F15: EA | G15: 1 | H15: 4359000
D16: 폴드 핸즈온 테이블 | E16: [집기제작] - 2,400X1,700X950 - 2T SUS H/L, 갈바 레이저 절곡 및 재단작업, 코너용접 및 연마작업 - 30*30 각파이프 구조 보강 - 20*20 서스파이프 보강 및 키트 상판 레이저타공 - 쇼케이스 보강대 및 브라켓 제작 - 지정 분체 마감 | F16: EA | G16: 1 | H16: 8960000
C17: 플립존 | D17: 셀피 보태니컬 월 | E17: [집기제작] - 1,210X160X2,050 - 2T 갈바 레이저 절곡 및 재단작업, 코너용접 및 연마작업 - 30*30 각파이프 구조 보강 - 도어 경첩 하드웨어 - 지정 분체 마감 | F17: EA | G17: 1 | H17: 4615000
D18: 플립 셀피 월 | E18: [집기제작] - 1,210X210X2,050 - 2T 갈바 레이저 절곡 및 재단작업, 코너용접 및 연마작업 - 30*30 각파이프 구조 보강 - 도어 경첩 하드웨어 - 지정 분체 마감 | F18: EA | G18: 1 | H18: 4468000
D19: 셀피 프린트 테이블 | E19: [집기제작] - 1,200X400X950 - 1.5T 갈바 레이저 절곡 및 재단작업, 코너용접 및 연마작업 - 30*30 각파이프 구조 보강 - 지정 분체 마감 | F19: EA | G19: 1 | H19: 4375000
D20: 선반 거울 월 | E20: [집기제작] - 1,210X160X2,050 - 2T SUS H/L 레이저 절곡 및 재단작업, 코너용접 및 연마작업 - 30*30 각파이프 구조 보강 - 430X200X20T SUS H/L 선반 / 5T 은경+프레임 - 도어 경첩 하드웨어 - 지정 분체 마감 | F20: EA | G20: 1 | H20: 5348000
D21: 옷걸이 월 | E21: [집기제작] - 1360X320X2050 - 2T SUS H/L 레이저 절곡 및 재단작업, 코너용접 및 연마작업 - 30*30 각파이프 구조 보강 - 1,150X300X670 하부장 - 지정 분체 및 도장 마감 | F21: EA | G21: 1 | H21: 4790000
D22: 플립 핸즈온 테이블 | E22: [집기제작] - 2,400X1,700X950 - 2T SUS H/L, 갈바 레이저 절곡 및 재단작업, 코너용접 및 연마작업 - 30*30 각파이프 구조 보강 - 20*20 서스파이프 보강 및 키트 상판 레이저타공 - 쇼케이스 보강대 및 브라켓 제작 - 지정 분체 마감 | F22: EA | G22: 1 | H22: 8960000
C23: 베뉴 전반 | D23: 복합기 테이블 | E23: [집기제작] - 600X560X1,000 - 2T SUS H/L, 갈바 레이저 절곡 및 재단작업, 코너용접 및 연마작업 - 30*30 각파이프 구조 보강 | F23: EA | G23: 1 | H23: 4569000
D24: 삼성 판매 테이블 | E24: [집기제작] - 1,200X500X1,000 - 2T SUS H/L, 갈바 레이저 절곡 및 재단작업, 코너용접 및 연마작업 - 30*30 각파이프 구조 보강 - 지정 분체 마감 | F24: EA | G24: 1 | H24: 4714000
D25: 패밀리넷 테이블 | E25: [집기제작] - 900X500X1,000 - 2T SUS H/L, 갈바 레이저 절곡 및 재단작업, 코너용접 및 연마작업 - 30*30 각파이프 구조 보강 - 지정 분체 마감 | F25: EA | G25: 1 | H25: 5041000
D26: 삼판, 패밀리넷 의자 | E26: [집기제작] - 450X510X750 - 기성 바스툴 7개 | F26: EA | G26: 7 | H26: 770000
D27: 제작집기 반입/설치 | E27: [제작집기 반입] - 1톤 2대(경기파주->화성, 7월13일) - 3.5톤 1대(경기파주->화성, 7월13일) - 집기 반입 | F27: 식 | G27: 1 | H27: 3200000
E28: [제작집기 셋팅비] - 집기 양중, 집기 배치, 집기 조립 등의 현장 작업 | F28: 식 | G28: 1 | H28: 4300000
C29: 집기 제작 소계 | H29: =SUM(H12:H28) -> 107601700
C30: 집기 제작 합계 | H30: =TRUNC(H29,-3) -> 107601000
B31: 2. 전시 제작 | C31: 베뉴 전반 | D31: 가설 공사 | E31: [주변 보양 및 현장 정리] - 7,850X4,500 - 양중 동선 보양 및 현장 정리정돈 - 준공 청소 - 보양자재 포함 | F31: M2 | G31: =7.85*4.5 -> 35.325 | H31: 5000000
D32: 목공사 | E32: [베뉴 전체 바닥단] - 7,850X4,500 - 15T, 9T MDF NC 가공 - 철야 제작 및 현장 설치 작업 | F32: M2 | G32: =7.85*4.5 -> 35.325 | H32: 8120000
D33: 금속 공사 | E33: [바닥마감대] - 7,850+4,500+7,850+4,500 / 120X28 - 1.5T SUS H/L 절곡 및 용접 가공 - 철야 제작 및 현장 설치 작업 | F33: M | G33: =7.85+4.5+7.85+4.5 -> 24.7 | H33: 14856000
E34: [사이니지 박스 받침대] - 2,400X250X140 - 2T SUS H/L, 레이저 절곡 및 재단작업, 코너용접 및 연마작업 - Ø50 SUS 파이프 용접 - 철야 제작 및 현장 설치 작업 | F34: 식 | G34: 1
D35: 전기 공사 | E35: [분전반 및 배관배선] - F-CV 2.5 / F-CV 4 벽체 및 바닥 전열 배선 - SMPS포함 잡자재 등 | F35: M2 | G35: =7.85*4.5 -> 35.325 | H35: 4200000
E36: [콘센트 및 조명 설치] - 2구산업용노출콘센트 및 멀티콘센트 - 현장 설치 철야 작업
D37: 수장 공사 | E37: [기본 바닥 마감] - 7,850X4,500 - 지정 데코타일 마감 - 현장 설치 작업 | F37: M2 | G37: =7.85*4.5 -> 35.325 | H37: 3550000
D38: 그래픽 사인공사 | E38: [셀피존 그래픽] - 1,200X2,000 - 지정 그래픽 실사출력 - 철야 제작 및 현장 설치 작업 | F38: 식 | G38: 1 | H38: 2200000
E39: [5T 아크릴 스카시] - H:150 Galaxy Z Fold7ㅣZ Filp7 검정 도장 - 철야 제작 및 현장 설치 작업 | F39: 식 | G39: 1
D40: 영상하드웨어 공사 | E40: [TV 및 모니터 설치] - 32, 55인치 TV 및 모니터 설치(재활용 장비) - 통신, 영상케이블 배선 바닥, 벽체, 집기 포설작업 - 케이블, 잡자재 포함 - 현장 설치 작업 | F40: 식 | G40: 1 | H40: 1000000
D41: 안전 관리 공사 | E41: [안전 관리비] - 안전모, 안전화, 작업조끼, 경광봉, 안전벨트, 사다리아웃트리거, 말비계 낙상방지기 등 안전 장구류 - 불티방지막, 용접우산, 버미글라스, 기계톱날 커버, 글라인드 날커버 - 소화기 및 비상약품 등 | F41: 식 | G41: 1 | H41: 1500000
D42: 철거 공사 | E42: [구조물 철거 및 정리 정돈, 원복] - 구조물 및 집기 철거 작업 - 구조 철거 현장 작업 - 폐기물 처리비 - 철거 잡자재 및 공구사용 | F42: 식 | G42: 1 | H42: 12050000
E43: [재활용 집기 현장 철거 및 정리 정돈, 원복] - 5TON 윙바디 1대(화성->평택) 8월2일 - 집기 반출 현장 작업 - 평택 창고 입고 작업 | F43: 식 | G43: 1
C44: 전시 공사 소계 | H44: =SUM(H31:H43) -> 52476000
...
